Workbook

Sheet Inputs
A1: MONTHLY INPUTS — LIBERTY LIVING KPI DATA
A2: Enter the raw count for each row each month. The KPI Dashboard tab calculates rates and RAG automatically.
A4: Metric | B4: Hint / source | C4: Jan 2026 | D4: Feb 2026 | E4: Mar 2026 | F4: Apr 2026 | G4: May 2026 | H4: Jun 2026 | I4: Jul 2026 | J4: Aug 2026 | K4: Sep 2026 | L4: Oct 2026 | M4: Nov 2026 | N4: Dec 2026
A5: OPERATIONAL BASELINE
A6: Total hours delivered | B6: From CRM time-and-attendance report | G6: 19000
A7: Total visits scheduled | B7: From rota planning system | G7: 25400
A8: Total visits delivered | B8: Scheduled minus missed | G8: 25300
A9: Active Service Users (month end) | B9: From CRM Service User register | G9: 400
A10: Active staff (month end) | B10: From HR system | G10: 135
A11: Total medication prompts delivered | B11: From CRM medication log | G11: 15200
A12: SERVICE DELIVERY
A13: Missed visits | B13: Any visit not delivered for any reason | G13: 100
A14: Late visits (>30 mins late) | B14: Visits outside agreed time window | G14: 650
A15: Care plan reviews due in month | B15: Reviews falling due that month | G15: 33
A16: Care plan reviews completed | B16: Reviews completed on or before due date | G16: 32
A17: CLINICAL SAFETY
A18: Medication errors / near misses | B18: Any incident involving medication | G18: 6
A19: Falls reported | B19: Reported via incident form | G19: 9
A20: Major or Extreme incidents | B20: Rated 4-5 on HSE Risk Scoring Matrix | G20: 0
A21: Open Disclosure events triggered | B21: Incidents requiring formal OD per QA-13 | G21: 1
A22: Open Disclosure events completed in line with QA-13 | B22: Initial + formal stages closed | G22: 1
A23: SERVICE USER EXPERIENCE
A24: Complaints received | B24: Any channel including anonymous | G24: 2
A25: Complaints closed in month | B25: Used as denominator for resolution-time | G25: 3
A26: Sum of resolution days (closed) | B26: Add days-to-close for each closed complaint | G26: 48
A27: Complaints upheld or partly upheld | B27: Of those closed in the month | G27: 1
A28: Compliments received | B28: Any channel — log faithfully | G28: 14
A29: Service User satisfaction (annual only) | B29: From annual survey — enter once per year | G29: 0.92
A30: STAFF WORKFORCE
A31: Leavers in rolling 12 months | B31: Update each month with rolling total | G31: 24
A32: Sickness days lost in month | B32: From HR system | G32: 102
A33: Staff with all mandatory training in date | B33: From LMS | G33: 131
A34: Staff with supervision recorded at cadence | B34: From HR system | G34: 129
A35: Staff with valid NVB vetting | B35: From HR vetting register | G35: 135
A36: GOVERNANCE & COMPLIANCE
A37: Safeguarding concerns raised | B37: All concerns logged in month | G37: 2
A38: Statutory notifications due | B38: Patient Safety Act 2023, HIQA, HSE | G38: 3
A39: Statutory notifications submitted on time | B39: Of those due in month | G39: 3
A40: Audits planned YTD | B40: Cumulative from start of year | G40: 7
A41: Audits completed YTD | B41: Cumulative from start of year | G41: 7
...

Sheet KPI Dashboard
A1: KPI DASHBOARD — CALCULATED FROM MONTHLY INPUTS
A2: All values calculated from the Inputs tab. Conditional formatting flags Green / Amber / Red automatically.
A4: Category | B4: KPI | C4: How it's calculated | D4: Green | E4: Amber | F4: Red | G4: Liberty Living target | H4: Jan 2026 | I4: Feb 2026 | J4: Mar 2026 | K4: Apr 2026 | L4: May 2026 | M4: Jun 2026 | N4: Jul 2026 | O4: Aug 2026 | P4: Sep 2026 | Q4: Oct 2026 | R4: Nov 2026 | S4: Dec 2026 | T4: Latest | U4: Trend (last 3m) | V4: RAG
A5: Service Delivery | B5: Visit completion rate | C5: (visits_delivered ÷ visits_scheduled) | D5: ≥99% | E5: 97–98.9% | F5: <97% | G5: ≥99% (≤253 missed of ~25,300 visits) | H5: =IFERROR(Inputs!C8/Inputs!C7,"") | I5: =IFERROR(Inputs!D8/Inputs!D7,"") | J5: =IFERROR(Inputs!E8/Inputs!E7,"") | K5: =IFERROR(Inputs!F8/Inputs!F7,"") | L5: =IFERROR(Inputs!G8/Inputs!G7,"") -> 0.99606299 | M5: =IFERROR(Inputs!H8/Inputs!H7,"") | N5: =IFERROR(Inputs!I8/Inputs!I7,"") | O5: =IFERROR(Inputs!J8/Inputs!J7,"") | ... S5: =IFERROR(Inputs!N8/Inputs!N7,"") | T5: =IFERROR(LOOKUP(2,1/(H5:S5<>""),H5:S5),"") -> 0.99606299 | U5: =IFERROR(IF(AND(COUNT(Q5:S5)>0,COUNT(N5:P5)>0),IF(AVERAGE(Q5:S5)>AVERAGE(N5:P5),"▲ up",IF(AVERAGE(Q5:S5)<AVERAGE(N5:P5),"▼ down","◆ flat")),""),"") | V5: =IF(T5="","",IF(NOT(ISNUMBER(T5)),"n/a",IF(T5>=0.99,"Green",IF(T5>=0.97,"Amber","Red")))) -> Green
A6: Service Delivery | B6: Missed visit rate | C6: (missed_visits ÷ visits_scheduled) | D6: ≤0.5% | E6: 0.5–1% | F6: >1% | G6: ≤127 missed visits/mo (~0.5% of 25,300) | H6: =IFERROR(Inputs!C13/Inputs!C7,"") | I6: =IFERROR(Inputs!D13/Inputs!D7,"") | J6: =IFERROR(Inputs!E13/Inputs!E7,"") | K6: =IFERROR(Inputs!F13/Inputs!F7,"") | L6: =IFERROR(Inputs!G13/Inputs!G7,"") -> 0.0039370079 | M6: =IFERROR(Inputs!H13/Inputs!H7,"") | N6: =IFERROR(Inputs!I13/Inputs!I7,"") | O6: =IFERROR(Inputs!J13/Inputs!J7,"") | ... S6: =IFERROR(Inputs!N13/Inputs!N7,"") | T6: =IFERROR(LOOKUP(2,1/(H6:S6<>""),H6:S6),"") -> 0.0039370079 | U6: =IFERROR(IF(AND(COUNT(Q6:S6)>0,COUNT(N6:P6)>0),IF(AVERAGE(Q6:S6)>AVERAGE(N6:P6),"▲ up",IF(AVERAGE(Q6:S6)<AVERAGE(N6:P6),"▼ down","◆ flat")),""),"") | V6: =IF(T6="","",IF(NOT(ISNUMBER(T6)),"n/a",IF(T6<=0.005,"Green",IF(T6<=0.01,"Amber","Red")))) -> Green
A7: Service Delivery | B7: Late visit rate (>30 min) | C7: (late_visits ÷ visits_delivered) | D7: ≤3% | E7: 3–5% | F7: >5% | G7: ≤760 late visits/mo (~3% of 25,300) | H7: =IFERROR(Inputs!C14/Inputs!C8,"") | I7: =IFERROR(Inputs!D14/Inputs!D8,"") | J7: =IFERROR(Inputs!E14/Inputs!E8,"") | K7: =IFERROR(Inputs!F14/Inputs!F8,"") | L7: =IFERROR(Inputs!G14/Inputs!G8,"") -> 0.0256917 | M7: =IFERROR(Inputs!H14/Inputs!H8,"") | N7: =IFERROR(Inputs!I14/Inputs!I8,"") | O7: =IFERROR(Inputs!J14/Inputs!J8,"") | ... S7: =IFERROR(Inputs!N14/Inputs!N8,"") | T7: =IFERROR(LOOKUP(2,1/(H7:S7<>""),H7:S7),"") -> 0.0256917 | U7: =IFERROR(IF(AND(COUNT(Q7:S7)>0,COUNT(N7:P7)>0),IF(AVERAGE(Q7:S7)>AVERAGE(N7:P7),"▲ up",IF(AVERAGE(Q7:S7)<AVERAGE(N7:P7),"▼ down","◆ flat")),""),"") | V7: =IF(T7="","",IF(NOT(ISNUMBER(T7)),"n/a",IF(T7<=0.03,"Green",IF(T7<=0.05,"Amber","Red")))) -> Green
A8: Service Delivery | B8: Care plan review compliance | C8: (reviews_done ÷ reviews_due) | D8: 100% | E8: 95–99.9% | F8: <95% | G8: 100% of reviews due in month | H8: =IFERROR(Inputs!C16/Inputs!C15,"") | I8: =IFERROR(Inputs!D16/Inputs!D15,"") | J8: =IFERROR(Inputs!E16/Inputs!E15,"") | K8: =IFERROR(Inputs!F16/Inputs!F15,"") | L8: =IFERROR(Inputs!G16/Inputs!G15,"") -> 0.96969697 | M8: =IFERROR(Inputs!H16/Inputs!H15,"") | N8: =IFERROR(Inputs!I16/Inputs!I15,"") | O8: =IFERROR(Inputs!J16/Inputs!J15,"") | ... S8: =IFERROR(Inputs!N16/Inputs!N15,"") | T8: =IFERROR(LOOKUP(2,1/(H8:S8<>""),H8:S8),"") -> 0.96969697 | U8: =IFERROR(IF(AND(COUNT(Q8:S8)>0,COUNT(N8:P8)>0),IF(AVERAGE(Q8:S8)>AVERAGE(N8:P8),"▲ up",IF(AVERAGE(Q8:S8)<AVERAGE(N8:P8),"▼ down","◆ flat")),""),"") | V8: =IF(T8="","",IF(NOT(ISNUMBER(T8)),"n/a",IF(T8>=1,"Green",IF(T8>=0.95,"Amber","Red")))) -> Amber
A9: Clinical Safety | B9: Medication errors per 1,000 prompts | C9: (med_errors ÷ med_prompts) × 1,000 | D9: ≤0.5 | E9: 0.5–1.0 | F9: >1.0 | G9: ≤8 errors/mo (~15,200 prompts) | H9: =IFERROR((Inputs!C18/Inputs!C11)*1000,"") | I9: =IFERROR((Inputs!D18/Inputs!D11)*1000,"") | J9: =IFERROR((Inputs!E18/Inputs!E11)*1000,"") | K9: =IFERROR((Inputs!F18/Inputs!F11)*1000,"") | L9: =IFERROR((Inputs!G18/Inputs!G11)*1000,"") -> 0.39473684 | M9: =IFERROR((Inputs!H18/Inputs!H11)*1000,"") | N9: =IFERROR((Inputs!I18/Inputs!I11)*1000,"") | O9: =IFERROR((Inputs!J18/Inputs!J11)*1000,"") | ... S9: =IFERROR((Inputs!N18/Inputs!N11)*1000,"") | T9: =IFERROR(LOOKUP(2,1/(H9:S9<>""),H9:S9),"") -> 0.39473684 | U9: =IFERROR(IF(AND(COUNT(Q9:S9)>0,COUNT(N9:P9)>0),IF(AVERAGE(Q9:S9)>AVERAGE(N9:P9),"▲ up",IF(AVERAGE(Q9:S9)<AVERAGE(N9:P9),"▼ down","◆ flat")),""),"") | V9: =IF(T9="","",IF(NOT(ISNUMBER(T9)),"n/a",IF(T9<=0.5,"Green",IF(T9<=1,"Amber","Red")))) -> Green
A10: Clinical Safety | B10: Falls per 100 Service Users | C10: (falls ÷ active_sus) × 100 | D10: ≤3 | E10: 3–5 | F10: >5 | G10: ≤12 falls/mo across 400 SUs | H10: =IFERROR((Inputs!C19/Inputs!C9)*100,"") | I10: =IFERROR((Inputs!D19/Inputs!D9)*100,"") | J10: =IFERROR((Inputs!E19/Inputs!E9)*100,"") | K10: =IFERROR((Inputs!F19/Inputs!F9)*100,"") | L10: =IFERROR((Inputs!G19/Inputs!G9)*100,"") -> 2.25 | M10: =IFERROR((Inputs!H19/Inputs!H9)*100,"") | N10: =IFERROR((Inputs!I19/Inputs!I9)*100,"") | O10: =IFERROR((Inputs!J19/Inputs!J9)*100,"") | ... S10: =IFERROR((Inputs!N19/Inputs!N9)*100,"") | T10: =IFERROR(LOOKUP(2,1/(H10:S10<>""),H10:S10),"") -> 2.25 | U10: =IFERROR(IF(AND(COUNT(Q10:S10)>0,COUNT(N10:P10)>0),IF(AVERAGE(Q10:S10)>AVERAGE(N10:P10),"▲ up",IF(AVERAGE(Q10:S10)<AVERAGE(N10:P10),"▼ down","◆ flat")),""),"") | V10: =IF(T10="","",IF(NOT(ISNUMBER(T10)),"n/a",IF(T10<=3,"Green",IF(T10<=5,"Amber","Red")))) -> Green
A11: Clinical Safety | B11: Serious incidents (Major/Extreme) | C11: Count direct from inputs | D11: 0 | E11: 1–2 | F11: ≥3 | G11: 0 per month | H11: =IFERROR(Inputs!C20,"") -> 0 | I11: =IFERROR(Inputs!D20,"") -> 0 | J11: =IFERROR(Inputs!E20,"") -> 0 | K11: =IFERROR(Inputs!F20,"") -> 0 | L11: =IFERROR(Inputs!G20,"") -> 0 | M11: =IFERROR(Inputs!H20,"") -> 0 | N11: =IFERROR(Inputs!I20,"") -> 0 | O11: =IFERROR(Inputs!J20,"") -> 0 | ... S11: =IFERROR(Inputs!N20,"") -> 0 | T11: =IFERROR(LOOKUP(2,1/(H11:S11<>""),H11:S11),"") -> 0 | U11: =IFERROR(IF(AND(COUNT(Q11:S11)>0,COUNT(N11:P11)>0),IF(AVERAGE(Q11:S11)>AVERAGE(N11:P11),"▲ up",IF(AVERAGE(Q11:S11)<AVERAGE(N11:P11),"▼ down","◆ flat")),""),"") -> ◆ flat | V11: =IF(T11="","",IF(NOT(ISNUMBER(T11)),"n/a",IF(T11=0,"Green",IF(T11<=2,"Amber","Red")))) -> Green
A12: Clinical Safety | B12: Open Disclosure compliance | C12: (od_completed ÷ od_required) | D12: 100% | E12: 90–99% | F12: <90% | G12: 100% of qualifying events | H12: =IF(Inputs!C21=0,"n/a",IFERROR(Inputs!C22/Inputs!C21,"")) -> n/a | I12: =IF(Inputs!D21=0,"n/a",IFERROR(Inputs!D22/Inputs!D21,"")) -> n/a | J12: =IF(Inputs!E21=0,"n/a",IFERROR(Inputs!E22/Inputs!E21,"")) -> n/a | K12: =IF(Inputs!F21=0,"n/a",IFERROR(Inputs!F22/Inputs!F21,"")) -> n/a | L12: =IF(Inputs!G21=0,"n/a",IFERROR(Inputs!G22/Inputs!G21,"")) -> 1 | M12: =IF(Inputs!H21=0,"n/a",IFERROR(Inputs!H22/Inputs!H21,"")) -> n/a | N12: =IF(Inputs!I21=0,"n/a",IFERROR(Inputs!I22/Inputs!I21,"")) -> n/a | O12: =IF(Inputs!J21=0,"n/a",IFERROR(Inputs!J22/Inputs!J21,"")) -> n/a | ... S12: =IF(Inputs!N21=0,"n/a",IFERROR(Inputs!N22/Inputs!N21,"")) -> n/a | T12: =IFERROR(LOOKUP(2,1/(H12:S12<>""),H12:S12),"") -> n/a | U12: =IFERROR(IF(AND(COUNT(Q12:S12)>0,COUNT(N12:P12)>0),IF(AVERAGE(Q12:S12)>AVERAGE(N12:P12),"▲ up",IF(AVERAGE(Q12:S12)<AVERAGE(N12:P12),"▼ down","◆ flat")),""),"") | V12: =IF(T12="","",IF(NOT(ISNUMBER(T12)),"n/a",IF(T12>=1,"Green",IF(T12>=0.9,"Amber","Red")))) -> n/a
A13: Service User Experience | B13: Complaints volume | C13: Count direct | D13: Trend tracked | E13: Trend tracked | F13: Trend tracked | G13: Trend only (typical 1–2/mo at this scale) | H13: =IFERROR(Inputs!C24,"") -> 0 | I13: =IFERROR(Inputs!D24,"") -> 0 | J13: =IFERROR(Inputs!E24,"") -> 0 | K13: =IFERROR(Inputs!F24,"") -> 0 | L13: =IFERROR(Inputs!G24,"") -> 2 | M13: =IFERROR(Inputs!H24,"") -> 0 | N13: =IFERROR(Inputs!I24,"") -> 0 | O13: =IFERROR(Inputs!J24,"") -> 0 | ... S13: =IFERROR(Inputs!N24,"") -> 0 | T13: =IFERROR(LOOKUP(2,1/(H13:S13<>""),H13:S13),"") -> 2 | U13: =IFERROR(IF(AND(COUNT(Q13:S13)>0,COUNT(N13:P13)>0),IF(AVERAGE(Q13:S13)>AVERAGE(N13:P13),"▲ up",IF(AVERAGE(Q13:S13)<AVERAGE(N13:P13),"▼ down","◆ flat")),""),"") -> ◆ flat | V13: =IF(T13="","","Trend") -> Trend
A14: Service User Experience | B14: Avg complaint resolution time (days) | C14: (complaint_days_sum ÷ complaints_closed) | D14: ≤20 | E14: 20–30 | F14: >30 | G14: Median ≤20 working days | H14: =IF(Inputs!C25=0,"n/a",IFERROR(Inputs!C26/Inputs!C25,"")) -> n/a | I14: =IF(Inputs!D25=0,"n/a",IFERROR(Inputs!D26/Inputs!D25,"")) -> n/a | J14: =IF(Inputs!E25=0,"n/a",IFERROR(Inputs!E26/Inputs!E25,"")) -> n/a | K14: =IF(Inputs!F25=0,"n/a",IFERROR(Inputs!F26/Inputs!F25,"")) -> n/a | L14: =IF(Inputs!G25=0,"n/a",IFERROR(Inputs!G26/Inputs!G25,"")) -> 16 | M14: =IF(Inputs!H25=0,"n/a",IFERROR(Inputs!H26/Inputs!H25,"")) -> n/a | N14: =IF(Inputs!I25=0,"n/a",IFERROR(Inputs!I26/Inputs!I25,"")) -> n/a | O14: =IF(Inputs!J25=0,"n/a",IFERROR(Inputs!J26/Inputs!J25,"")) -> n/a | ... S14: =IF(Inputs!N25=0,"n/a",IFERROR(Inputs!N26/Inputs!N25,"")) -> n/a | T14: =IFERROR(LOOKUP(2,1/(H14:S14<>""),H14:S14),"") -> n/a | U14: =IFERROR(IF(AND(COUNT(Q14:S14)>0,COUNT(N14:P14)>0),IF(AVERAGE(Q14:S14)>AVERAGE(N14:P14),"▲ up",IF(AVERAGE(Q14:S14)<AVERAGE(N14:P14),"▼ down","◆ flat")),""),"") | V14: =IF(T14="","",IF(NOT(ISNUMBER(T14)),"n/a",IF(T14<=20,"Green",IF(T14<=30,"Amber","Red")))) -> n/a
A15: Service User Experience | B15: Complaints upheld % | C15: (complaints_upheld ÷ complaints_closed) | D15: Trend tracked | E15: Trend tracked | F15: Trend tracked | G15: Trend only — interpret in context | H15: =IF(Inputs!C25=0,"n/a",IFERROR(Inputs!C27/Inputs!C25,"")) -> n/a | I15: =IF(Inputs!D25=0,"n/a",IFERROR(Inputs!D27/Inputs!D25,"")) -> n/a | J15: =IF(Inputs!E25=0,"n/a",IFERROR(Inputs!E27/Inputs!E25,"")) -> n/a | K15: =IF(Inputs!F25=0,"n/a",IFERROR(Inputs!F27/Inputs!F25,"")) -> n/a | L15: =IF(Inputs!G25=0,"n/a",IFERROR(Inputs!G27/Inputs!G25,"")) -> 0.33333333 | M15: =IF(Inputs!H25=0,"n/a",IFERROR(Inputs!H27/Inputs!H25,"")) -> n/a | N15: =IF(Inputs!I25=0,"n/a",IFERROR(Inputs!I27/Inputs!I25,"")) -> n/a | O15: =IF(Inputs!J25=0,"n/a",IFERROR(Inputs!J27/Inputs!J25,"")) -> n/a | ... S15: =IF(Inputs!N25=0,"n/a",IFERROR(Inputs!N27/Inputs!N25,"")) -> n/a | T15: =IFERROR(LOOKUP(2,1/(H15:S15<>""),H15:S15),"") -> n/a | U15: =IFERROR(IF(AND(COUNT(Q15:S15)>0,COUNT(N15:P15)>0),IF(AVERAGE(Q15:S15)>AVERAGE(N15:P15),"▲ up",IF(AVERAGE(Q15:S15)<AVERAGE(N15:P15),"▼ down","◆ flat")),""),"") | V15: =IF(T15="","","Trend") -> Trend
A16: Service User Experience | B16: Service User satisfaction | C16: Annual survey result (enter once/year) | D16: ≥90% | E16: 80–89% | F16: <80% | G16: ≥90% annual survey score | H16: =IFERROR(Inputs!C29,"") -> 0 | I16: =IFERROR(Inputs!D29,"") -> 0 | J16: =IFERROR(Inputs!E29,"") -> 0 | K16: =IFERROR(Inputs!F29,"") -> 0 | L16: =IFERROR(Inputs!G29,"") -> 0.92 | M16: =IFERROR(Inputs!H29,"") -> 0 | N16: =IFERROR(Inputs!I29,"") -> 0 | O16: =IFERROR(Inputs!J29,"") -> 0 | ... S16: =IFERROR(Inputs!N29,"") -> 0 | T16: =IFERROR(LOOKUP(2,1/(H16:S16<>""),H16:S16),"") -> 0.92 | U16: =IFERROR(IF(AND(COUNT(Q16:S16)>0,COUNT(N16:P16)>0),IF(AVERAGE(Q16:S16)>AVERAGE(N16:P16),"▲ up",IF(AVERAGE(Q16:S16)<AVERAGE(N16:P16),"▼ down","◆ flat")),""),"") -> ◆ flat | V16: =IF(T16="","",IF(NOT(ISNUMBER(T16)),"n/a",IF(T16>=0.9,"Green",IF(T16>=0.8,"Amber","Red")))) -> Green
A17: Service User Experience | B17: Compliments received | C17: Count direct | D17: Trend tracked | E17: Trend tracked | F17: Trend tracked | G17: Aim for ≥5 compliments per complaint | H17: =IFERROR(Inputs!C28,"") -> 0 | I17: =IFERROR(Inputs!D28,"") -> 0 | J17: =IFERROR(Inputs!E28,"") -> 0 | K17: =IFERROR(Inputs!F28,"") -> 0 | L17: =IFERROR(Inputs!G28,"") -> 14 | M17: =IFERROR(Inputs!H28,"") -> 0 | N17: =IFERROR(Inputs!I28,"") -> 0 | O17: =IFERROR(Inputs!J28,"") -> 0 | ... S17: =IFERROR(Inputs!N28,"") -> 0 | T17: =IFERROR(LOOKUP(2,1/(H17:S17<>""),H17:S17),"") -> 14 | U17: =IFERROR(IF(AND(COUNT(Q17:S17)>0,COUNT(N17:P17)>0),IF(AVERAGE(Q17:S17)>AVERAGE(N17:P17),"▲ up",IF(AVERAGE(Q17:S17)<AVERAGE(N17:P17),"▼ down","◆ flat")),""),"") -> ◆ flat | V17: =IF(T17="","","Trend") -> Trend
A18: Staff Workforce | B18: Annual staff turnover % | C18: (leavers_12m ÷ active_staff) | D18: ≤20% | E18: 20–30% | F18: >30% | G18: ≤27 leavers/year (135 staff) | H18: =IFERROR(Inputs!C31/Inputs!C10,"") | I18: =IFERROR(Inputs!D31/Inputs!D10,"") | J18: =IFERROR(Inputs!E31/Inputs!E10,"") | K18: =IFERROR(Inputs!F31/Inputs!F10,"") | L18: =IFERROR(Inputs!G31/Inputs!G10,"") -> 0.17777778 | M18: =IFERROR(Inputs!H31/Inputs!H10,"") | N18: =IFERROR(Inputs!I31/Inputs!I10,"") | O18: =IFERROR(Inputs!J31/Inputs!J10,"") | ... S18: =IFERROR(Inputs!N31/Inputs!N10,"") | T18: =IFERROR(LOOKUP(2,1/(H18:S18<>""),H18:S18),"") -> 0.17777778 | U18: =IFERROR(IF(AND(COUNT(Q18:S18)>0,COUNT(N18:P18)>0),IF(AVERAGE(Q18:S18)>AVERAGE(N18:P18),"▲ up",IF(AVERAGE(Q18:S18)<AVERAGE(N18:P18),"▼ down","◆ flat")),""),"") | V18: =IF(T18="","",IF(NOT(ISNUMBER(T18)),"n/a",IF(T18<=0.2,"Green",IF(T18<=0.3,"Amber","Red")))) -> Green
A19: Staff Workforce | B19: Staff sickness rate | C19: (sickness_days ÷ (active_staff × 22)) | D19: ≤4% | E19: 4–6% | F19: >6% | G19: ≤119 sickness days/mo | H19: =IFERROR(Inputs!C32/(Inputs!C10*22),"") | I19: =IFERROR(Inputs!D32/(Inputs!D10*22),"") | J19: =IFERROR(Inputs!E32/(Inputs!E10*22),"") | K19: =IFERROR(Inputs!F32/(Inputs!F10*22),"") | L19: =IFERROR(Inputs!G32/(Inputs!G10*22),"") -> 0.034343434 | M19: =IFERROR(Inputs!H32/(Inputs!H10*22),"") | N19: =IFERROR(Inputs!I32/(Inputs!I10*22),"") | O19: =IFERROR(Inputs!J32/(Inputs!J10*22),"") | ... S19: =IFERROR(Inputs!N32/(Inputs!N10*22),"") | T19: =IFERROR(LOOKUP(2,1/(H19:S19<>""),H19:S19),"") -> 0.034343434 | U19: =IFERROR(IF(AND(COUNT(Q19:S19)>0,COUNT(N19:P19)>0),IF(AVERAGE(Q19:S19)>AVERAGE(N19:P19),"▲ up",IF(AVERAGE(Q19:S19)<AVERAGE(N19:P19),"▼ down","◆ flat")),""),"") | V19: =IF(T19="","",IF(NOT(ISNUMBER(T19)),"n/a",IF(T19<=0.04,"Green",IF(T19<=0.06,"Amber","Red")))) -> Green
A20: Staff Workforce | B20: Mandatory training compliance | C20: (training_compliant ÷ active_staff) | D20: ≥95% | E20: 90–94.9% | F20: <90% | G20: ≥129 of 135 staff | H20: =IFERROR(Inputs!C33/Inputs!C10,"") | I20: =IFERROR(Inputs!D33/Inputs!D10,"") | J20: =IFERROR(Inputs!E33/Inputs!E10,"") | K20: =IFERROR(Inputs!F33/Inputs!F10,"") | L20: =IFERROR(Inputs!G33/Inputs!G10,"") -> 0.97037037 | M20: =IFERROR(Inputs!H33/Inputs!H10,"") | N20: =IFERROR(Inputs!I33/Inputs!I10,"") | O20: =IFERROR(Inputs!J33/Inputs!J10,"") | ... S20: =IFERROR(Inputs!N33/Inputs!N10,"") | T20: =IFERROR(LOOKUP(2,1/(H20:S20<>""),H20:S20),"") -> 0.97037037 | U20: =IFERROR(IF(AND(COUNT(Q20:S20)>0,COUNT(N20:P20)>0),IF(AVERAGE(Q20:S20)>AVERAGE(N20:P20),"▲ up",IF(AVERAGE(Q20:S20)<AVERAGE(N20:P20),"▼ down","◆ flat")),""),"") | V20: =IF(T20="","",IF(NOT(ISNUMBER(T20)),"n/a",IF(T20>=0.95,"Green",IF(T20>=0.9,"Amber","Red")))) -> Green
A21: Staff Workforce | B21: Supervision compliance | C21: (supervision_compliant ÷ active_staff) | D21: ≥95% | E21: 90–94.9% | F21: <90% | G21: ≥129 of 135 staff | H21: =IFERROR(Inputs!C34/Inputs!C10,"") | I21: =IFERROR(Inputs!D34/Inputs!D10,"") | J21: =IFERROR(Inputs!E34/Inputs!E10,"") | K21: =IFERROR(Inputs!F34/Inputs!F10,"") | L21: =IFERROR(Inputs!G34/Inputs!G10,"") -> 0.95555556 | M21: =IFERROR(Inputs!H34/Inputs!H10,"") | N21: =IFERROR(Inputs!I34/Inputs!I10,"") | O21: =IFERROR(Inputs!J34/Inputs!J10,"") | ... S21: =IFERROR(Inputs!N34/Inputs!N10,"") | T21: =IFERROR(LOOKUP(2,1/(H21:S21<>""),H21:S21),"") -> 0.95555556 | U21: =IFERROR(IF(AND(COUNT(Q21:S21)>0,COUNT(N21:P21)>0),IF(AVERAGE(Q21:S21)>AVERAGE(N21:P21),"▲ up",IF(AVERAGE(Q21:S21)<AVERAGE(N21:P21),"▼ down","◆ flat")),""),"") | V21: =IF(T21="","",IF(NOT(ISNUMBER(T21)),"n/a",IF(T21>=0.95,"Green",IF(T21>=0.9,"Amber","Red")))) -> Green
A22: Staff Workforce | B22: Garda vetting currency | C22: (nvb_current ÷ active_staff) | D22: 100% | E22: 99–99.9% | F22: <99% | G22: All 135 in date | H22: =IFERROR(Inputs!C35/Inputs!C10,"") | I22: =IFERROR(Inputs!D35/Inputs!D10,"") | J22: =IFERROR(Inputs!E35/Inputs!E10,"") | K22: =IFERROR(Inputs!F35/Inputs!F10,"") | L22: =IFERROR(Inputs!G35/Inputs!G10,"") -> 1 | M22: =IFERROR(Inputs!H35/Inputs!H10,"") | N22: =IFERROR(Inputs!I35/Inputs!I10,"") | O22: =IFERROR(Inputs!J35/Inputs!J10,"") | ... S22: =IFERROR(Inputs!N35/Inputs!N10,"") | T22: =IFERROR(LOOKUP(2,1/(H22:S22<>""),H22:S22),"") -> 1 | U22: =IFERROR(IF(AND(COUNT(Q22:S22)>0,COUNT(N22:P22)>0),IF(AVERAGE(Q22:S22)>AVERAGE(N22:P22),"▲ up",IF(AVERAGE(Q22:S22)<AVERAGE(N22:P22),"▼ down","◆ flat")),""),"") | V22: =IF(T22="","",IF(NOT(ISNUMBER(T22)),"n/a",IF(T22>=1,"Green",IF(T22>=0.99,"Amber","Red")))) -> Green
A23: Governance & Compliance | B23: Safeguarding concerns raised | C23: Count direct | D23: Trend tracked | E23: Trend tracked | F23: Trend tracked | G23: Trend only (0 is not the target) | H23: =IFERROR(Inputs!C37,"") -> 0 | I23: =IFERROR(Inputs!D37,"") -> 0 | J23: =IFERROR(Inputs!E37,"") -> 0 | K23: =IFERROR(Inputs!F37,"") -> 0 | L23: =IFERROR(Inputs!G37,"") -> 2 | M23: =IFERROR(Inputs!H37,"") -> 0 | N23: =IFERROR(Inputs!I37,"") -> 0 | O23: =IFERROR(Inputs!J37,"") -> 0 | ... S23: =IFERROR(Inputs!N37,"") -> 0 | T23: =IFERROR(LOOKUP(2,1/(H23:S23<>""),H23:S23),"") -> 2 | U23: =IFERROR(IF(AND(COUNT(Q23:S23)>0,COUNT(N23:P23)>0),IF(AVERAGE(Q23:S23)>AVERAGE(N23:P23),"▲ up",IF(AVERAGE(Q23:S23)<AVERAGE(N23:P23),"▼ down","◆ flat")),""),"") -> ◆ flat | V23: =IF(T23="","","Trend") -> Trend
A24: Governance & Compliance | B24: Statutory notifications on time | C24: (stat_notif_on_time ÷ stat_notif_total) | D24: 100% | E24: Any miss | F24: Any miss | G24: 100% — no exceptions | H24: =IF(Inputs!C38=0,"n/a",IFERROR(Inputs!C39/Inputs!C38,"")) -> n/a | I24: =IF(Inputs!D38=0,"n/a",IFERROR(Inputs!D39/Inputs!D38,"")) -> n/a | J24: =IF(Inputs!E38=0,"n/a",IFERROR(Inputs!E39/Inputs!E38,"")) -> n/a | K24: =IF(Inputs!F38=0,"n/a",IFERROR(Inputs!F39/Inputs!F38,"")) -> n/a | L24: =IF(Inputs!G38=0,"n/a",IFERROR(Inputs!G39/Inputs!G38,"")) -> 1 | M24: =IF(Inputs!H38=0,"n/a",IFERROR(Inputs!H39/Inputs!H38,"")) -> n/a | N24: =IF(Inputs!I38=0,"n/a",IFERROR(Inputs!I39/Inputs!I38,"")) -> n/a | O24: =IF(Inputs!J38=0,"n/a",IFERROR(Inputs!J39/Inputs!J38,"")) -> n/a | ... S24: =IF(Inputs!N38=0,"n/a",IFERROR(Inputs!N39/Inputs!N38,"")) -> n/a | T24: =IFERROR(LOOKUP(2,1/(H24:S24<>""),H24:S24),"") -> n/a | U24: =IFERROR(IF(AND(COUNT(Q24:S24)>0,COUNT(N24:P24)>0),IF(AVERAGE(Q24:S24)>AVERAGE(N24:P24),"▲ up",IF(AVERAGE(Q24:S24)<AVERAGE(N24:P24),"▼ down","◆ flat")),""),"") | V24: =IF(T24="","",IF(NOT(ISNUMBER(T24)),"n/a",IF(T24>=1,"Green",IF(T24>=0.999,"Amber","Red")))) -> n/a
A25: Governance & Compliance | B25: Audits completed vs plan | C25: (audits_done_ytd ÷ audits_planned_ytd) | D25: ≥95% | E25: 85–94.9% | F25: <85% | G25: ≥17 of 18 annual audits | H25: =IFERROR(Inputs!C41/Inputs!C40,"") | I25: =IFERROR(Inputs!D41/Inputs!D40,"") | J25: =IFERROR(Inputs!E41/Inputs!E40,"") | K25: =IFERROR(Inputs!F41/Inputs!F40,"") | L25: =IFERROR(Inputs!G41/Inputs!G40,"") -> 1 | M25: =IFERROR(Inputs!H41/Inputs!H40,"") | N25: =IFERROR(Inputs!I41/Inputs!I40,"") | O25: =IFERROR(Inputs!J41/Inputs!J40,"") | ... S25: =IFERROR(Inputs!N41/Inputs!N40,"") | T25: =IFERROR(LOOKUP(2,1/(H25:S25<>""),H25:S25),"") -> 1 | U25: =IFERROR(IF(AND(COUNT(Q25:S25)>0,COUNT(N25:P25)>0),IF(AVERAGE(Q25:S25)>AVERAGE(N25:P25),"▲ up",IF(AVERAGE(Q25:S25)<AVERAGE(N25:P25),"▼ down","◆ flat")),""),"") | V25: =IF(T25="","",IF(NOT(ISNUMBER(T25)),"n/a",IF(T25>=0.95,"Green",IF(T25>=0.85,"Amber","Red")))) -> Green
A26: Governance & Compliance | B26: Audit findings closed within SLA | C26: (findings_closed ÷ findings_due) | D26: ≥90% | E26: 80–89.9% | F26: <80% | G26: ≥90% of audit findings due | H26: =IF(Inputs!C42=0,"n/a",IFERROR(Inputs!C43/Inputs!C42,"")) -> n/a | I26: =IF(Inputs!D42=0,"n/a",IFERROR(Inputs!D43/Inputs!D42,"")) -> n/a | J26: =IF(Inputs!E42=0,"n/a",IFERROR(Inputs!E43/Inputs!E42,"")) -> n/a | K26: =IF(Inputs!F42=0,"n/a",IFERROR(Inputs!F43/Inputs!F42,"")) -> n/a | L26: =IF(Inputs!G42=0,"n/a",IFERROR(Inputs!G43/Inputs!G42,"")) -> 0.88888889 | M26: =IF(Inputs!H42=0,"n/a",IFERROR(Inputs!H43/Inputs!H42,"")) -> n/a | N26: =IF(Inputs!I42=0,"n/a",IFERROR(Inputs!I43/Inputs!I42,"")) -> n/a | O26: =IF(Inputs!J42=0,"n/a",IFERROR(Inputs!J43/Inputs!J42,"")) -> n/a | ... S26: =IF(Inputs!N42=0,"n/a",IFERROR(Inputs!N43/Inputs!N42,"")) -> n/a | T26: =IFERROR(LOOKUP(2,1/(H26:S26<>""),H26:S26),"") -> n/a | U26: =IFERROR(IF(AND(COUNT(Q26:S26)>0,COUNT(N26:P26)>0),IF(AVERAGE(Q26:S26)>AVERAGE(N26:P26),"▲ up",IF(AVERAGE(Q26:S26)<AVERAGE(N26:P26),"▼ down","◆ flat")),""),"") | V26: =IF(T26="","",IF(NOT(ISNUMBER(T26)),"n/a",IF(T26>=0.9,"Green",IF(T26>=0.8,"Amber","Red")))) -> n/a
A27: Governance & Compliance | B27: Open QIPs (month end) | C27: Count direct | D27: Trend tracked | E27: Trend tracked | F27: Trend tracked | G27: Trend only — typical 20–40 | H27: =IFERROR(Inputs!C44,"") -> 0 | I27: =IFERROR(Inputs!D44,"") -> 0 | J27: =IFERROR(Inputs!E44,"") -> 0 | K27: =IFERROR(Inputs!F44,"") -> 0 | L27: =IFERROR(Inputs!G44,"") -> 26 | M27: =IFERROR(Inputs!H44,"") -> 0 | N27: =IFERROR(Inputs!I44,"") -> 0 | O27: =IFERROR(Inputs!J44,"") -> 0 | ... S27: =IFERROR(Inputs!N44,"") -> 0 | T27: =IFERROR(LOOKUP(2,1/(H27:S27<>""),H27:S27),"") -> 26 | U27: =IFERROR(IF(AND(COUNT(Q27:S27)>0,COUNT(N27:P27)>0),IF(AVERAGE(Q27:S27)>AVERAGE(N27:P27),"▲ up",IF(AVERAGE(Q27:S27)<AVERAGE(N27:P27),"▼ down","◆ flat")),""),"") -> ◆ flat | V27: =IF(T27="","","Trend") -> Trend
A28: Governance & Compliance | B28: QIP closure within target | C28: (qips_closed_on_time ÷ qips_target_due) | D28: ≥85% | E28: 70–84.9% | F28: <70% | G28: ≥85% of QIPs closed by target | H28: =IF(Inputs!C45=0,"n/a",IFERROR(Inputs!C46/Inputs!C45,"")) -> n/a | I28: =IF(Inputs!D45=0,"n/a",IFERROR(Inputs!D46/Inputs!D45,"")) -> n/a | J28: =IF(Inputs!E45=0,"n/a",IFERROR(Inputs!E46/Inputs!E45,"")) -> n/a | K28: =IF(Inputs!F45=0,"n/a",IFERROR(Inputs!F46/Inputs!F45,"")) -> n/a | L28: =IF(Inputs!G45=0,"n/a",IFERROR(Inputs!G46/Inputs!G45,"")) -> 0.8 | M28: =IF(Inputs!H45=0,"n/a",IFERROR(Inputs!H46/Inputs!H45,"")) -> n/a | N28: =IF(Inputs!I45=0,"n/a",IFERROR(Inputs!I46/Inputs!I45,"")) -> n/a | O28: =IF(Inputs!J45=0,"n/a",IFERROR(Inputs!J46/Inputs!J45,"")) -> n/a | ... S28: =IF(Inputs!N45=0,"n/a",IFERROR(Inputs!N46/Inputs!N45,"")) -> n/a | T28: =IFERROR(LOOKUP(2,1/(H28:S28<>""),H28:S28),"") -> n/a | U28: =IFERROR(IF(AND(COUNT(Q28:S28)>0,COUNT(N28:P28)>0),IF(AVERAGE(Q28:S28)>AVERAGE(N28:P28),"▲ up",IF(AVERAGE(Q28:S28)<AVERAGE(N28:P28),"▼ down","◆ flat")),""),"") | V28: =IF(T28="","",IF(NOT(ISNUMBER(T28)),"n/a",IF(T28>=0.85,"Green",IF(T28>=0.7,"Amber","Red")))) -> n/a
A29: Governance & Compliance | B29: Policies within review date | C29: (policies_in_date ÷ policies_total) | D29: 100% | E29: 95–99.9% | F29: <95% | G29: All 42 in date | H29: =IFERROR(Inputs!C47/Inputs!C48,"") | I29: =IFERROR(Inputs!D47/Inputs!D48,"") | J29: =IFERROR(Inputs!E47/Inputs!E48,"") | K29: =IFERROR(Inputs!F47/Inputs!F48,"") | L29: =IFERROR(Inputs!G47/Inputs!G48,"") -> 1 | M29: =IFERROR(Inputs!H47/Inputs!H48,"") | N29: =IFERROR(Inputs!I47/Inputs!I48,"") | O29: =IFERROR(Inputs!J47/Inputs!J48,"") | ... S29: =IFERROR(Inputs!N47/Inputs!N48,"") | T29: =IFERROR(LOOKUP(2,1/(H29:S29<>""),H29:S29),"") -> 1 | U29: =IFERROR(IF(AND(COUNT(Q29:S29)>0,COUNT(N29:P29)>0),IF(AVERAGE(Q29:S29)>AVERAGE(N29:P29),"▲ up",IF(AVERAGE(Q29:S29)<AVERAGE(N29:P29),"▼ down","◆ flat")),""),"") | V29: =IF(T29="","",IF(NOT(ISNUMBER(T29)),"n/a",IF(T29>=1,"Green",IF(T29>=0.95,"Amber","Red")))) -> Green

Sheet Summary
B2: KPI Dashboard — Snapshot
B3: Live counts pulled from the calculated dashboard. Bring this to every EMT meeting.
B5: KPIs being tracked | C5: =COUNTA('KPI Dashboard'!B5:B29) -> 25
B6: KPIs reporting data | C6: =COUNT('KPI Dashboard'!T5:T29) -> 19
B7: KPIs Green | C7: =COUNTIF('KPI Dashboard'!V5:V29,"Green") -> 14
B8: KPIs Amber | C8: =COUNTIF('KPI Dashboard'!V5:V29,"Amber") -> 1
B9: KPIs Red | C9: =COUNTIF('KPI Dashboard'!V5:V29,"Red") -> 0
B10: KPIs Trend-only | C10: =COUNTIF('KPI Dashboard'!V5:V29,"Trend") -> 5
B13: By category
B14: Category | C14: Tracked | D14: Green | E14: Amber | F14: Red
B15: Service Delivery | C15: =COUNTIF('KPI Dashboard'!A5:A29,"Service Delivery") -> 4 | D15: =COUNTIFS('KPI Dashboard'!A5:A29,"Service Delivery",'KPI Dashboard'!V5:V29,"Green") -> 3 | E15: =COUNTIFS('KPI Dashboard'!A5:A29,"Service Delivery",'KPI Dashboard'!V5:V29,"Amber") -> 1 | F15: =COUNTIFS('KPI Dashboard'!A5:A29,"Service Delivery",'KPI Dashboard'!V5:V29,"Red") -> 0
B16: Clinical Safety | C16: =COUNTIF('KPI Dashboard'!A5:A29,"Clinical Safety") -> 4 | D16: =COUNTIFS('KPI Dashboard'!A5:A29,"Clinical Safety",'KPI Dashboard'!V5:V29,"Green") -> 3 | E16: =COUNTIFS('KPI Dashboard'!A5:A29,"Clinical Safety",'KPI Dashboard'!V5:V29,"Amber") -> 0 | F16: =COUNTIFS('KPI Dashboard'!A5:A29,"Clinical Safety",'KPI Dashboard'!V5:V29,"Red") -> 0
B17: Service User Experience | C17: =COUNTIF('KPI Dashboard'!A5:A29,"Service User Experience") -> 5 | D17: =COUNTIFS('KPI Dashboard'!A5:A29,"Service User Experience",'KPI Dashboard'!V5:V29,"Green") -> 1 | E17: =COUNTIFS('KPI Dashboard'!A5:A29,"Service User Experience",'KPI Dashboard'!V5:V29,"Amber") -> 0 | F17: =COUNTIFS('KPI Dashboard'!A5:A29,"Service User Experience",'KPI Dashboard'!V5:V29,"Red") -> 0
B18: Staff Workforce | C18: =COUNTIF('KPI Dashboard'!A5:A29,"Staff Workforce") -> 5 | D18: =COUNTIFS('KPI Dashboard'!A5:A29,"Staff Workforce",'KPI Dashboard'!V5:V29,"Green") -> 5 | E18: =COUNTIFS('KPI Dashboard'!A5:A29,"Staff Workforce",'KPI Dashboard'!V5:V29,"Amber") -> 0 | F18: =COUNTIFS('KPI Dashboard'!A5:A29,"Staff Workforce",'KPI Dashboard'!V5:V29,"Red") -> 0
B19: Governance & Compliance | C19: =COUNTIF('KPI Dashboard'!A5:A29,"Governance & Compliance") -> 7 | D19: =COUNTIFS('KPI Dashboard'!A5:A29,"Governance & Compliance",'KPI Dashboard'!V5:V29,"Green") -> 2 | E19: =COUNTIFS('KPI Dashboard'!A5:A29,"Governance & Compliance",'KPI Dashboard'!V5:V29,"Amber") -> 0 | F19: =COUNTIFS('KPI Dashboard'!A5:A29,"Governance & Compliance",'KPI Dashboard'!V5:V29,"Red") -> 0

Sheet How to use
B2: How to use this dashboard
B4: The model in one line:
B5: The Quality team enters RAW COUNTS each month (50 missed visits, 8 falls, 2 complaints, etc.) on the Inputs tab. The KPI Dashboard tab calculates rates and RAG automatically.
B7: Step 1 — Update the operational baseline
B8: On the Inputs tab, top section (Operational baseline), enter the six month-end figures: total hours delivered, visits scheduled, visits delivered, active Service Users, active staff, total medication prompts. These are the denominators for the rest of the calculations.
B10: Step 2 — Enter the numerators
B11: Working down the Inputs tab, enter the count for each KPI numerator: missed visits, falls, medication errors, complaints, leavers, sickness days, training compliant staff, statutory notifications, audit findings, QIPs, and so on. Where a row needs only a count (e.g. compliments, Open QIPs), enter the count directly.
B13: Step 3 — Review the KPI Dashboard
B14: Switch to the KPI Dashboard tab. Every cell shows the calculated rate for that month. Conditional formatting colours each cell Green / Amber / Red against the Liberty Living target. The 'Trend' column shows the direction of the last 3 months vs the previous 3.
B16: Step 4 — Brief EMT
B17: Open the Summary tab. The top-line shows how many KPIs are Green, Amber and Red right now, with a breakdown by category. Screenshot this into the monthly EMT pack.
B19: Step 5 — Brief CGC quarterly
... B32: The May 2026 column is pre-populated as a worked example showing how the dashboard responds to a typical month. Clear the May column once you start using the workbook with real data, or overwrite as the real values come in.
