Workbook

Sheet Overview
B2: Liberty Living Homecare — Audit Working Pack
B3: 10 inspection-grade audit pro formas, one tab each. Issued by CEO Shauna Delaney, May 2026.
B5: How to use
B6: • Each tab is a single audit. Open the tab, complete the header (auditor, dates, sample), then score each criterion 0 / 1 / 2 / N/A.
B7: • Weighted scoring is automatic. The overall audit compliance % calculates as you complete the scores.
B8: • Findings rating (Compliant / Substantially / Partially / Non-compliant) is set automatically against the % thresholds.
B9: • Record evidence and observations in the wide column next to each criterion. Then complete the recommendations and action plan.
B10: • Sign off at the bottom. Lift any actions into the QIP Register in the QMS Implementation Tracker.
B12: Audit summary register
B13: Code | C13: Audit | D13: Source policies | E13: Owner | F13: Frequency | G13: Last audit | H13: Compliance % | I13: Rating
B14: AUD-CP-01 | C14: Care Plan Audit | D14: CARE-08, CARE-27, CARE-02, IM-30 | E14: Quality Lead (Clinical Lead is the operational owner of Home Support Care Plans per CARE-08 s.5.3; the Director of Quality / Quality Lead conducts the independent audit) | F14: Annual full-cycle audit, supplemented by quarterly thematic dip-sampling and a bi-annual audit by the Clinical Lead per IM-30 s.9.1 | H14: ='CP-01 Care Plan Audit'!F46 | I14: ='CP-01 Care Plan Audit'!H46
B15: AUD-MED-01 | C15: Medication Prompting Audit | D15: CARE-20, CARE-06 | E15: Clinical Lead (operational accountability per CARE-20 s.11.1) with independent verification by Director of Quality | F15: Bi-annual full audit, with quarterly KPI review on adverse drug reactions and missed-dose logs | H15: ='MED-01 Medication Prompting Aud'!F44 | I15: ='MED-01 Medication Prompting Aud'!H44
B16: AUD-IPC-01 | C16: Infection Prevention and Control Audit | D16: HS-15, HS-34 | E16: Clinical Lead (IPC lead role per HS-15 s.5.2) with independent verification by Director of Quality | F16: Annual full audit, supplemented by quarterly hand-hygiene compliance observation and any outbreak-triggered audits | H16: ='IPC-01 Infection Prevention and'!F45 | I16: ='IPC-01 Infection Prevention and'!H45
B17: AUD-SG-01 | C17: Safeguarding Audit | D17: HS-23, HS-23.1, HS-28, CARE-09, CARE-17 | E17: Designated Safeguarding Officer (DSO) leads with independent verification by Director of Quality. The DSO is the operational lead per HS-23.1 s.5.4. | F17: Annual full audit, plus quarterly thematic review of all safeguarding alerts and preliminary screenings, plus immediate review following any Trust in Care event involving a staff member | H17: ='SG-01 Safeguarding Audit'!F47 | I17: ='SG-01 Safeguarding Audit'!H47
B18: AUD-CMP-01 | C18: Complaints Handling Audit | D18: QA-03, QA-03.2, QA-SOP-CMP-01 | E18: Complaints Review Officer (per QA-03 s.5.5) with independent oversight by Director of Quality | F18: Annual full audit, plus quarterly KPI review aligned to QA-03 s.15.0 Quarterly Report to the HSE | H18: ='CMP-01 Complaints Handling Audi'!F46 | I18: ='CMP-01 Complaints Handling Audi'!H46
B19: AUD-FIN-01 | C19: Financial Protection Audit | D19: CARE-09, CARE-17 | E19: Director of Care (per CARE-09 s.5.4 and CARE-17 s.5.0) with independent verification by Director of Quality. The Director of Care holds quarterly audit responsibility per CARE-17 s.8.10. | F19: Quarterly audit of Financial Transactions records (mandated by CARE-17 s.8.10); annual full audit covering all controls | H19: ='FIN-01 Financial Protection Aud'!F44 | I19: ='FIN-01 Financial Protection Aud'!H44
B20: AUD-LW-01 | C20: Lone Worker Audit | D20: HS-16, HS-10 | E20: Director of Operations (per HS-16 s.5.4) with independent verification by Director of Quality | F20: Annual full audit, plus quarterly review of lone-working incidents, missed control-point contacts, and aggression incidents | H20: ='LW-01 Lone Worker Audit'!F44 | I20: ='LW-01 Lone Worker Audit'!H44
B21: AUD-ENV-01 | C21: Environmental Safety Audit | D21: HS-24, HS-10, HS-31 | E21: Director of Operations (per HS-24 s.4.5) with verification by Director of Quality | F21: Annual full audit, plus quarterly review of new Home Environmental Risk Assessments and any environment-related incidents | H21: ='ENV-01 Environmental Safety Aud'!F46 | I21: ='ENV-01 Environmental Safety Aud'!H46
B22: AUD-REC-01 | C22: Record-Keeping and Data Audit | D22: IM-30, IM-05 | E22: Director of Quality (per IM-30 s.9.2) with the Data Protection Officer (DPO) auditing GDPR compliance per IM-05 | F22: Quarterly record-quality audit (per IM-30 s.9.2) and bi-annual Home Support Plan audit by Clinical Lead (per IM-30 s.9.1); annual full GDPR / Data Protection audit | H22: ='REC-01 Record-Keeping and Data '!F46 | I22: ='REC-01 Record-Keeping and Data '!H46
B23: AUD-TRG-01 | C23: Training and Competency Audit | D23: HR-14, HR-29, HR-38 | E23: Director of Operations / HR Director jointly (HR-14 s.5.5 / s.5.6) with independent verification by Director of Quality | F23: Annual full audit, plus quarterly review of the training matrix for currency and gaps | H23: ='TRG-01 Training and Competency '!F49 | I23: ='TRG-01 Training and Competency '!H49

Sheet CP-01 Care Plan Audit
A1: AUD-CP-01 · Care Plan Audit
A3: Audit code | B3: AUD-CP-01
A4: Title | B4: Care Plan Audit
A5: Source policies | B5: CARE-08, CARE-27, CARE-02, IM-30
A6: Owner | B6: Quality Lead (Clinical Lead is the operational owner of Home Support Care Plans per CARE-08 s.5.3; the Director of Quality / Quality Lead conducts the independent audit)
A7: Frequency | B7: Annual full-cycle audit, supplemented by quarterly thematic dip-sampling and a bi-annual audit by the Clinical Lead per IM-30 s.9.1
A8: Auditor name | B8: [enter auditor name]
A9: Audit period | B9: [enter audit period]
A10: Sample size | B10: [enter sample size]
A12: SCOPE & SAMPLING METHODOLOGY
A13: Scope | B13: All Service User Home Support Care Plans active at any point in the audit period, including HSE-authorised packages and private packages. Plans for discharged Service Users within the period are included for closure/transition criteria.
A14: Sampling | B14: Stratified random sample drawn from the active Service User CRM list. Sample size: minimum 15% of active plans or 40 plans, whichever is greater (HSE Authorisation Scheme expectation). Stratification: by Client Services Manager area (proportional), and by complexity tier (standard / complex / dementia / palliative). Risk-weighting overlay: 100% of plans where an incident, complaint or safeguarding concern was recorded in the period are pulled in addition. Exclusions: plans created within 7 days of audit cut-off (insufficient data). Period covered: rolling 12 months ending audit cut-off date. Sampling frame and seed are recorded in the audit working pack for reproducibility.
A15: Data sources | B15: • Service User CRM records • Hard-copy / signed Home Support Care Plans in the Service User Home Folder (CARE-08 Appendix 4) • Service User Internal Folder (CARE-08 Appendix 5) • Signed Charter of Rights and Responsibilities (CARE-02) • Signed Consent to Share (CARE-08 Appendix 14) • Initial Assessment records (CARE-08 Appendix 1, 2) • Environmental Risk Assessment (CARE-08 Appendix 8) • Falls Risk Assessment (CARE-08 Appendix 9) • Medication Risk Assessment (CARE-08 Appendix 10) • Home Care Record sheets (CARE-08 Appendix 13) • Client Review records (CARE-08 Appendix 12) • HSE Authorisation Scheme service authorisation documents • Getting to Know Me document (CARE-08 Appendix 7)
A17: SCORING SCHEME
A18: 0 = Non-compliant · 1 = Partially compliant · 2 = Fully compliant · N/A = Not applicable. Weighted score = score × weight. Audit compliance % = sum of weighted scores ÷ (sum of maximum weighted scores, excluding N/A).
A20: AUDIT CRITERIA
A21: ID | B21: Criterion | C21: Policy ref | D21: Weight | E21: Score (0/1/2/N/A) | F21: Weighted score | G21: Evidence / observations | H21: Comments
A22: CP-01 | B22: A current Home Support Care Plan exists for every sampled Service User receiving services | C22: CARE-08 s.6.13 | D22: 5 | F22: =IF(E22="","",IF(UPPER(E22)="N/A","N/A",D22*E22)) | G22: • Locate plan in CRM and physical folder • Confirm date of creation precedes first service date
A23: CP-02 | B23: Plan was developed following an Initial Assessment conducted by a competent assessor (Client Services Manager or Clinical Lead) | C23: CARE-08 s.6.4 / s.6.6 | D23: 5 | F23: =IF(E23="","",IF(UPPER(E23)="N/A","N/A",D23*E23)) | G23: • Assessor named and signature present • Assessor role/qualification recorded
A24: CP-03 | B24: Plan was developed and signed off within the timeframe required before service commencement | C24: CARE-08 s.6.13 | D24: 5 | F24: =IF(E24="","",IF(UPPER(E24)="N/A","N/A",D24*E24)) | G24: • Compare plan agreement date to first visit date • Identify any service delivered without an agreed plan
A25: CP-04 | B25: Plan content covers all CARE-08 minimum domains (personal care, mobility, nutrition, medication, social, communication, end-of-life preferences as applicable) | C25: CARE-08 s.6.6 / s.7.0 | D25: 4 | F25: =IF(E25="","",IF(UPPER(E25)="N/A","N/A",D25*E25)) | G25: • Tick against domain checklist in working paper • Note any blank/N/A entries without rationale
A26: CP-05 | B26: Service User preferences, will, cultural and religious practices are documented and reflected in the plan | C26: CARE-02 (FREDA); CARE-27 s.7.4 | D26: 3 | F26: =IF(E26="","",IF(UPPER(E26)="N/A","N/A",D26*E26)) | G26: • Cross-reference Getting to Know Me document • Look for narrative entries not just tick-boxes
A27: CP-06 | B27: Service User signature (or recorded consent if signature not possible) is present on the plan and on the Charter of Rights and Responsibilities | C27: CARE-08 s.7.13; CARE-02 | D27: 5 | F27: =IF(E27="","",IF(UPPER(E27)="N/A","N/A",D27*E27)) | G27: • Signature or recorded verbal consent with witness • Date of signature matches plan agreement date
A28: CP-07 | B28: Where the Service User has a Decision Support Arrangement, AHD or EPA, this is identified in the plan and respected in care decisions | C28: CARE-08 s.7.11 | D28: 5 | F28: =IF(E28="","",IF(UPPER(E28)="N/A","N/A",D28*E28)) | G28: • Look for DSA/AHD/EPA entry on cover sheet • Confirm representative contact details captured
A29: CP-08 | B29: Plan content remains within the scope of the authorised HSE Home Support Service for the Service User | C29: CARE-08 s.7.1 | D29: 4 | F29: =IF(E29="","",IF(UPPER(E29)="N/A","N/A",D29*E29)) | G29: • Compare planned tasks against HSE authorisation hours and task list • Flag any tasks outside scope
A30: CP-09 | B30: Risk assessments (environmental, falls, medication, lone worker) are completed and dated, with control measures in the plan | C30: CARE-08 s.7.8 / s.7.9; HS-31; HS-16 | D30: 5 | F30: =IF(E30="","",IF(UPPER(E30)="N/A","N/A",D30*E30)) | G30: • All four assessments present • Control measures cross-referenced in care tasks
A31: CP-10 | B31: Plan was reviewed at least every 3 months, or sooner following a change in need or incident | C31: CARE-08 s.10.0; IM-30 s.9.1 | D31: 4 | F31: =IF(E31="","",IF(UPPER(E31)="N/A","N/A",D31*E31)) | G31: • Review log present • Trigger-based reviews evident after recorded incidents
A32: CP-11 | B32: Review records show evidence of Service User involvement in the review | C32: CARE-27 s.7.4 | D32: 3 | F32: =IF(E32="","",IF(UPPER(E32)="N/A","N/A",D32*E32)) | G32: • SU comments recorded • SU signature on review
A33: CP-12 | B33: Plan version control is in place - superseded versions retained, current version clearly marked | C33: IM-30 s.6.7 | D33: 2 | F33: =IF(E33="","",IF(UPPER(E33)="N/A","N/A",D33*E33)) | G33: • Version number on each page • Superseded versions retrievable
... A43: CP-22 | B43: Where the Service User is private (non-HSE), an equivalent assessment and plan exists | C43: CARE-08 s.6.14 | D43: 3 | F43: =IF(E43="","",IF(UPPER(E43)="N/A","N/A",D43*E43)) | G43: • Private package flag in CRM • Plan structure equivalent to HSE plan
A45: COMPLIANCE SUMMARY
A46: Achieved weighted score | B46: =SUMPRODUCT(IFERROR((F22:F43+0),0)) -> 0 | C46: Max possible (excl N/A) | D46: =SUMPRODUCT((F22:F43<>"N/A")*(F22:F43<>"")*(D22:D43*2)) -> 0 | E46: Compliance % | F46: =IFERROR(B46/D46,"") | G46: Rating | H46: =IFERROR(IF(F46="","",IF(F46>=0.95,"Compliant",IF(F46>=0.85,"Substantially compliant",IF(F46>=0.7,"Partially compliant","Non-compliant")))),"")
A48: Rating thresholds: Compliant ≥95% · Substantially compliant 85-94.9% · Partially compliant 70-84.9% · Non-compliant <70%
A50: KEY FINDINGS
A51: [Auditor: summarise the main findings — strengths, areas of partial compliance and areas of non-compliance. Reference criterion IDs where relevant.]
A56: RECOMMENDATIONS
A57: [Auditor: list specific, actionable recommendations to address the findings. Each will become a QIP.]
A61: ACTION PLAN
A62: # | B62: Action | C62: Owner | D62: Target date | E62: Status | F62: Linked QIP ID | G62: Evidence of completion | H62: Closed date
A63: 1
...

Sheet MED-01 Medication Prompting Aud
A1: AUD-MED-01 · Medication Prompting Audit
A3: Audit code | B3: AUD-MED-01
A4: Title | B4: Medication Prompting Audit
A5: Source policies | B5: CARE-20, CARE-06
A6: Owner | B6: Clinical Lead (operational accountability per CARE-20 s.11.1) with independent verification by Director of Quality
A7: Frequency | B7: Bi-annual full audit, with quarterly KPI review on adverse drug reactions and missed-dose logs
A8: Auditor name | B8: [enter auditor name]
A9: Audit period | B9: [enter audit period]
A10: Sample size | B10: [enter sample size]
A12: SCOPE & SAMPLING METHODOLOGY
A13: Scope | B13: All Service Users for whom Liberty Living provides medication prompting (excluding self-managing Service Users), and all HCAs delivering prompting in the audit period.
A14: Sampling | B14: Two parallel samples. (1) Service User sample: 100% of Service Users with a Medication Risk Assessment indicating prompting required, OR a minimum of 30 if the prompting population exceeds 200. Random stratified by Client Services Manager area. (2) Staff competency sample: 20% of HCAs delivering prompting in the period, drawn at random, with 100% inclusion of any HCA who was the subject of a medication-related incident. Period: rolling 6 months. Exclusions: Service Users who self-manage (CARE-20 s.6.1) - they appear only in a separate self-management line-item count.
A15: Data sources | B15: • Service User CRM medication section • Signed Consent to Prompt Medication (CARE-20 Appendix 1) • Medication Risk Assessment (CARE-08 Appendix 10) • Home Support Care Plan medication section • Home Care Record sheets - medication prompting entries • HCA training records (Medication Management module) • National Carer Competency Assessment (NCCA) records • Incident log (QA-13) - medication category • Adverse Drug Reaction reports • GP / Pharmacy correspondence on file
A17: SCORING SCHEME
A18: 0 = Non-compliant · 1 = Partially compliant · 2 = Fully compliant · N/A = Not applicable. Weighted score = score × weight. Audit compliance % = sum of weighted scores ÷ (sum of maximum weighted scores, excluding N/A).
A20: AUDIT CRITERIA
A21: ID | B21: Criterion | C21: Policy ref | D21: Weight | E21: Score (0/1/2/N/A) | F21: Weighted score | G21: Evidence / observations | H21: Comments
A22: MED-01 | B22: A signed Consent to Prompt Medication form is on file for every Service User receiving prompting | C22: CARE-20 s.6.4; Appendix 1 | D22: 5 | F22: =IF(E22="","",IF(UPPER(E22)="N/A","N/A",D22*E22)) | G22: • Locate signed form • Confirm signed by SU or capacity-appropriate representative
A23: MED-02 | B23: Consent form is current (signed within last 12 months or following any change to medication regimen) | C23: CARE-20 s.6.4; CARE-06 | D23: 4 | F23: =IF(E23="","",IF(UPPER(E23)="N/A","N/A",D23*E23)) | G23: • Check date on consent • Cross-reference last medication change
A24: MED-03 | B24: A Medication Risk Assessment is completed and dated, identifying the level and form of prompting required | C24: CARE-20 s.6.3 | D24: 5 | F24: =IF(E24="","",IF(UPPER(E24)="N/A","N/A",D24*E24)) | G24: • Assessment present • Risk level recorded
A25: MED-04 | B25: Medication list in the plan matches the current prescription / pharmacy MAR sheet | C25: CARE-20 s.7.0 | D25: 4 | F25: =IF(E25="","",IF(UPPER(E25)="N/A","N/A",D25*E25)) | G25: • Compare plan list to MAR / blister-pack labels • Note discrepancies
A26: MED-05 | B26: Plan clearly limits HCA activity to prompting only - no administration, no removal from packaging | C26: CARE-20 s.7.2 / s.7.4 | D26: 5 | F26: =IF(E26="","",IF(UPPER(E26)="N/A","N/A",D26*E26)) | G26: • Wording explicit • No tasks like administer or dispense present
A27: MED-06 | B27: HCAs delivering prompting hold current Medication Management training and NCCA sign-off | C27: CARE-20 s.7.1; HR-14 | D27: 5 | F27: =IF(E27="","",IF(UPPER(E27)="N/A","N/A",D27*E27)) | G27: • Training cert date • NCCA on staff file
A28: MED-07 | B28: Every prompting episode is logged in the Home Care Record / CRM (date, time, prompt outcome) | C28: CARE-20 s.8.1 / s.8.2 | D28: 4 | F28: =IF(E28="","",IF(UPPER(E28)="N/A","N/A",D28*E28)) | G28: • Sample one month of visits • Look for missed log entries
A29: MED-08 | B29: Missed doses or Service User refusals are recorded and escalated to the Client Services Manager | C29: CARE-20 s.7.7 | D29: 5 | F29: =IF(E29="","",IF(UPPER(E29)="N/A","N/A",D29*E29)) | G29: • Refusal log entries • Escalation evidence
A30: MED-09 | B30: Adverse Drug Reactions are managed per CARE-20 s.9.0 and reported as incidents per QA-13 | C30: CARE-20 s.9.1 / s.9.2 | D30: 5 | F30: =IF(E30="","",IF(UPPER(E30)="N/A","N/A",D30*E30)) | G30: • ADR log entries • Linked QA-13 incident reports
A31: MED-10 | B31: Where capacity concerns arise in relation to medication, they are escalated per CARE-06 | C31: CARE-20 s.7.8 | D31: 4 | F31: =IF(E31="","",IF(UPPER(E31)="N/A","N/A",D31*E31)) | G31: • Capacity flag in CRM • Clinical Lead review
A32: MED-11 | B32: Obtaining prescriptions is not a routine HCA task, and where it occurs it is explicitly authorised in the plan | C32: CARE-20 s.6.5 / s.6.6 | D32: 3 | F32: =IF(E32="","",IF(UPPER(E32)="N/A","N/A",D32*E32)) | G32: • Plan entry authorising collection • Audit trail of collection
A33: MED-12 | B33: Medication-related entries follow good record-keeping practice - legible, dated, signed, no retrospective alteration | C33: IM-30 s.7.5 | D33: 2 | F33: =IF(E33="","",IF(UPPER(E33)="N/A","N/A",D33*E33)) | G33: • Visual inspection • Late entries appropriately flagged
... A41: MED-20 | B41: Confidentiality is maintained - medication information is not shared with third parties without consent | C41: CARE-20 s.7.3 / s.8.1 | D41: 4 | F41: =IF(E41="","",IF(UPPER(E41)="N/A","N/A",D41*E41)) | G41: • Consent to share scope • No unauthorised disclosures evident
A43: COMPLIANCE SUMMARY
A44: Achieved weighted score | B44: =SUMPRODUCT(IFERROR((F22:F41+0),0)) -> 0 | C44: Max possible (excl N/A) | D44: =SUMPRODUCT((F22:F41<>"N/A")*(F22:F41<>"")*(D22:D41*2)) -> 0 | E44: Compliance % | F44: =IFERROR(B44/D44,"") | G44: Rating | H44: =IFERROR(IF(F44="","",IF(F44>=0.95,"Compliant",IF(F44>=0.85,"Substantially compliant",IF(F44>=0.7,"Partially compliant","Non-compliant")))),"")
A46: Rating thresholds: Compliant ≥95% · Substantially compliant 85-94.9% · Partially compliant 70-84.9% · Non-compliant <70%
A48: KEY FINDINGS
A49: [Auditor: summarise the main findings — strengths, areas of partial compliance and areas of non-compliance. Reference criterion IDs where relevant.]
A54: RECOMMENDATIONS
A55: [Auditor: list specific, actionable recommendations to address the findings. Each will become a QIP.]
A59: ACTION PLAN
A60: # | B60: Action | C60: Owner | D60: Target date | E60: Status | F60: Linked QIP ID | G60: Evidence of completion | H60: Closed date
A61: 1
...

Sheet IPC-01 Infection Prevention and
A1: AUD-IPC-01 · Infection Prevention and Control Audit
A3: Audit code | B3: AUD-IPC-01
A4: Title | B4: Infection Prevention and Control Audit
A5: Source policies | B5: HS-15, HS-34
A6: Owner | B6: Clinical Lead (IPC lead role per HS-15 s.5.2) with independent verification by Director of Quality
A7: Frequency | B7: Annual full audit, supplemented by quarterly hand-hygiene compliance observation and any outbreak-triggered audits
A8: Auditor name | B8: [enter auditor name]
A9: Audit period | B9: [enter audit period]
A10: Sample size | B10: [enter sample size]
A12: SCOPE & SAMPLING METHODOLOGY
A13: Scope | B13: All operational areas of Liberty Living including office hubs, HCA practice in Service Users homes, PPE stock and distribution, the annual IPC Programme, and any current or recent outbreaks. Excludes Service User home environments outside the scope of Liberty Living-delivered care.
A14: Sampling | B14: Mixed methodology. (1) Document review - 100% of the IPC Programme, outbreak management plan, and PPE stock records. (2) Staff observation - direct observation of hand hygiene at five WHO moments for a random sample of 25 visits across HCAs (or 10% of the workforce, whichever is greater), conducted by the Clinical Lead or trained observer. (3) Staff knowledge check - short quiz with 30 randomly selected HCAs. (4) Service User home sample - 30 environmental risk assessments reviewed for IPC content. (5) Vaccination uptake - 100% review of the vaccination register. Period: rolling 12 months.
A15: Data sources | B15: • IPC Programme document (HS-15 s.7.1) • Outbreak Management Plan (HS-15 s.6.4) • PPE stock and distribution log • Staff vaccination register (Hep B, flu, COVID, others per NIAC) • Hand hygiene observation tool (WHO Five Moments) • Home Environmental Risk Assessment - IPC sections • Incident log - infection-related events • Training records - IPC and Hand Hygiene modules • HS-34 Hand Hygiene policy compliance evidence • Service User reports / complaints relating to IPC
A17: SCORING SCHEME
A18: 0 = Non-compliant · 1 = Partially compliant · 2 = Fully compliant · N/A = Not applicable. Weighted score = score × weight. Audit compliance % = sum of weighted scores ÷ (sum of maximum weighted scores, excluding N/A).
A20: AUDIT CRITERIA
A21: ID | B21: Criterion | C21: Policy ref | D21: Weight | E21: Score (0/1/2/N/A) | F21: Weighted score | G21: Evidence / observations | H21: Comments
A22: IPC-01 | B22: An annual IPC Programme exists, is signed off by CEO, and covers all elements required by HS-15 s.7.2 | C22: HS-15 s.7.1 / s.7.3 | D22: 5 | F22: =IF(E22="","",IF(UPPER(E22)="N/A","N/A",D22*E22)) | G22: • Locate signed Programme • Tick HS-15 s.7.2 elements
A23: IPC-02 | B23: The IPC Programme has been reviewed in the last 12 months | C23: HS-15 s.7.4 | D23: 3 | F23: =IF(E23="","",IF(UPPER(E23)="N/A","N/A",D23*E23)) | G23: • Last review date • Review minutes
A24: IPC-03 | B24: An Outbreak Management Plan is in place and accessible to operational staff | C24: HS-15 s.6.4 | D24: 5 | F24: =IF(E24="","",IF(UPPER(E24)="N/A","N/A",D24*E24)) | G24: • Locate plan • Confirm last test/drill date
A25: IPC-04 | B25: Sufficient numbers of staff are trained in IPC at all times to deliver the service safely | C25: HS-15 s.6.2 | D25: 4 | F25: =IF(E25="","",IF(UPPER(E25)="N/A","N/A",D25*E25)) | G25: • Training matrix coverage • Roster cross-check
A26: IPC-05 | B26: Staff vaccination register is maintained and offers documented per NIAC guidance | C26: HS-15 s.8.2 / s.8.4 | D26: 4 | F26: =IF(E26="","",IF(UPPER(E26)="N/A","N/A",D26*E26)) | G26: • Register completeness • Offer/refusal documented per staff
A27: IPC-06 | B27: Where staff declined vaccination, the risks were communicated and recorded | C27: HS-15 s.8.6 / s.8.7 | D27: 3 | F27: =IF(E27="","",IF(UPPER(E27)="N/A","N/A",D27*E27)) | G27: • Refusal record • Risk communication note
A28: IPC-07 | B28: Hand hygiene compliance against WHO Five Moments at observed visits is >=85% | C28: HS-15 s.9.4; HS-34 s.5 | D28: 5 | F28: =IF(E28="","",IF(UPPER(E28)="N/A","N/A",D28*E28)) | G28: • Observation audit results • Sample of 25 observations
A29: IPC-08 | B29: HCAs demonstrate correct hand washing technique per HS-34 s.6.1 | C29: HS-34 s.6.1 | D29: 4 | F29: =IF(E29="","",IF(UPPER(E29)="N/A","N/A",D29*E29)) | G29: • Direct observation • Knowledge check question
A30: IPC-09 | B30: HCAs demonstrate correct use of alcohol-based hand rub per HS-34 s.6.2 | C30: HS-34 s.6.2 | D30: 3 | F30: =IF(E30="","",IF(UPPER(E30)="N/A","N/A",D30*E30)) | G30: • Direct observation • Knowledge check question
A31: IPC-10 | B31: Gloves are used correctly - right indication, single-use, removed before leaving the home | C31: HS-34 s.7 | D31: 4 | F31: =IF(E31="","",IF(UPPER(E31)="N/A","N/A",D31*E31)) | G31: • Direct observation • Staff knowledge check
A32: IPC-11 | B32: PPE stock is sufficient, in-date, and accessible to all HCAs at start of each shift | C32: HS-15 s.9.0 | D32: 4 | F32: =IF(E32="","",IF(UPPER(E32)="N/A","N/A",D32*E32)) | G32: • Stock count • Expiry inspection • Distribution log
A33: IPC-12 | B33: Standard precautions are documented in plans where Service User condition requires (e.g. catheter, wound care, MRSA colonisation) | C33: HS-15 s.9.1 / s.9.7 | D33: 4 | F33: =IF(E33="","",IF(UPPER(E33)="N/A","N/A",D33*E33)) | G33: • Plan entries reviewed • Risk-specific precautions noted
... A42: IPC-21 | B42: IPC concerns identified by staff are escalated and resolved with documented action | C42: HS-15 s.5.1 | D42: 2 | F42: =IF(E42="","",IF(UPPER(E42)="N/A","N/A",D42*E42)) | G42: • Concern log • Closure evidence
A44: COMPLIANCE SUMMARY
A45: Achieved weighted score | B45: =SUMPRODUCT(IFERROR((F22:F42+0),0)) -> 0 | C45: Max possible (excl N/A) | D45: =SUMPRODUCT((F22:F42<>"N/A")*(F22:F42<>"")*(D22:D42*2)) -> 0 | E45: Compliance % | F45: =IFERROR(B45/D45,"") | G45: Rating | H45: =IFERROR(IF(F45="","",IF(F45>=0.95,"Compliant",IF(F45>=0.85,"Substantially compliant",IF(F45>=0.7,"Partially compliant","Non-compliant")))),"")
A47: Rating thresholds: Compliant ≥95% · Substantially compliant 85-94.9% · Partially compliant 70-84.9% · Non-compliant <70%
A49: KEY FINDINGS
A50: [Auditor: summarise the main findings — strengths, areas of partial compliance and areas of non-compliance. Reference criterion IDs where relevant.]
A55: RECOMMENDATIONS
A56: [Auditor: list specific, actionable recommendations to address the findings. Each will become a QIP.]
A60: ACTION PLAN
A61: # | B61: Action | C61: Owner | D61: Target date | E61: Status | F61: Linked QIP ID | G61: Evidence of completion | H61: Closed date
A62: 1
...

Sheet SG-01 Safeguarding Audit
A1: AUD-SG-01 · Safeguarding Audit
A3: Audit code | B3: AUD-SG-01
A4: Title | B4: Safeguarding Audit
A5: Source policies | B5: HS-23, HS-23.1, HS-28, CARE-09, CARE-17
A6: Owner | B6: Designated Safeguarding Officer (DSO) leads with independent verification by Director of Quality. The DSO is the operational lead per HS-23.1 s.5.4.
A7: Frequency | B7: Annual full audit, plus quarterly thematic review of all safeguarding alerts and preliminary screenings, plus immediate review following any Trust in Care event involving a staff member
A8: Auditor name | B8: [enter auditor name]
A9: Audit period | B9: [enter audit period]
A10: Sample size | B10: [enter sample size]
A12: SCOPE & SAMPLING METHODOLOGY
A13: Scope | B13: All safeguarding alerts, preliminary screenings, Trust in Care matters, financial protection records, and child welfare concerns raised or open in the audit period. Includes the Garda vetting register and the safeguarding training matrix.
A14: Sampling | B14: 100% review of all safeguarding alerts (typically a tractable volume in a 140-staff / 400-SU service). For prevention controls (vetting, training, environmental safeguards): 100% of staff records for vetting status and safeguarding training, plus a stratified 15% sample of Service User files for individual safeguarding risk assessment quality. Period: rolling 12 months. The audit is conducted by the Director of Quality independently of the DSO to ensure independent assurance. Any case where the DSO is conflicted is reviewed by an external safeguarding peer reviewer.
A15: Data sources | B15: • Safeguarding alerts log • HSE Preliminary Screening Forms PSF1 and PSF2 (HS-23.1 Appendix 2/3) • DSO case files • Trust in Care file (HS-23.1 s.10.0) • Child Safeguarding Statement (HS-28 Appendix 1) • Garda vetting register (NVB) • Staff training records (Safeguarding Vulnerable Adults; Children First e-Learning) • Service User Financial Transactions records (CARE-17 Appendix 1) • Incident log (QA-13) • Complaints log (QA-03) • EMT and Clinical Governance Committee minutes referencing safeguarding
A17: SCORING SCHEME
A18: 0 = Non-compliant · 1 = Partially compliant · 2 = Fully compliant · N/A = Not applicable. Weighted score = score × weight. Audit compliance % = sum of weighted scores ÷ (sum of maximum weighted scores, excluding N/A).
A20: AUDIT CRITERIA
A21: ID | B21: Criterion | C21: Policy ref | D21: Weight | E21: Score (0/1/2/N/A) | F21: Weighted score | G21: Evidence / observations | H21: Comments
A22: SG-01 | B22: A Designated Safeguarding Officer is appointed, named in policy, and contact details are visible to staff and Service Users | C22: HS-23.1 s.5.4 | D22: 5 | F22: =IF(E22="","",IF(UPPER(E22)="N/A","N/A",D22*E22)) | G22: • DSO named in current HS-23.1 • Posters/Service User Guide reference
A23: SG-02 | B23: Every staff member has current Garda Vetting (NVB) on file before commencing duties | C23: HR-29 s.14.0 | D23: 5 | F23: =IF(E23="","",IF(UPPER(E23)="N/A","N/A",D23*E23)) | G23: • 100% vetting register • Start date vs vetting date
A24: SG-03 | B24: Re-vetting is conducted at intervals not exceeding the policy-stated cycle | C24: HR-29 s.14.0 | D24: 4 | F24: =IF(E24="","",IF(UPPER(E24)="N/A","N/A",D24*E24)) | G24: • Re-vetting due-dates list • Overdue flags
A25: SG-04 | B25: All operational staff completed Safeguarding Vulnerable Adults training in the last 12 months | C25: HS-23 s.9.0 | D25: 5 | F25: =IF(E25="","",IF(UPPER(E25)="N/A","N/A",D25*E25)) | G25: • Training matrix • Certificate dates
A26: SG-05 | B26: All staff who may encounter children completed Children First e-Learning | C26: HS-28 s.6.10 | D26: 4 | F26: =IF(E26="","",IF(UPPER(E26)="N/A","N/A",D26*E26)) | G26: • Training matrix - Children First • Mandated Person list
A27: SG-06 | B27: Child Safeguarding Statement is published, displayed, and within review cycle | C27: HS-28 s.6.9 / Appendix 1 | D27: 4 | F27: =IF(E27="","",IF(UPPER(E27)="N/A","N/A",D27*E27)) | G27: • Locate Statement • Display evidence
A28: SG-07 | B28: Every safeguarding alert raised in the period has a Preliminary Screening completed using PSF1 within timeframe | C28: HS-23.1 s.9.2 | D28: 5 | F28: =IF(E28="","",IF(UPPER(E28)="N/A","N/A",D28*E28)) | G28: • Sample 100% of alerts • PSF1 on file
A29: SG-08 | B29: PSF1 outcomes are documented on PSF2 with a clear decision (no further action / further inquiry / refer to HSE Safeguarding and Protection Team) | C29: HS-23.1 s.9.2.7 / Appendix 3 | D29: 5 | F29: =IF(E29="","",IF(UPPER(E29)="N/A","N/A",D29*E29)) | G29: • PSF2 completion • Outcome rationale
A30: SG-09 | B30: Reasonable Grounds for Concern cases (Stage 3) were referred to the HSE Safeguarding and Protection Team | C30: HS-23.1 s.9.4 | D30: 5 | F30: =IF(E30="","",IF(UPPER(E30)="N/A","N/A",D30*E30)) | G30: • HSE referral letter • Acknowledgement on file
A31: SG-10 | B31: Allegations against staff members were managed under Trust in Care with appropriate protections | C31: HS-23.1 s.10.0 | D31: 5 | F31: =IF(E31="","",IF(UPPER(E31)="N/A","N/A",D31*E31)) | G31: • Trust in Care file • Suspension/precautionary measures documented
A32: SG-11 | B32: Service User disclosures were responded to per HS-23.1 Appendix 1 (believed, not interrogated, recorded verbatim where possible) | C32: HS-23.1 Appendix 1 | D32: 4 | F32: =IF(E32="","",IF(UPPER(E32)="N/A","N/A",D32*E32)) | G32: • Disclosure recording quality • Verbatim quotes vs paraphrase
A33: SG-12 | B33: Self-neglect cases are identified and managed per HS-23 s.8.0 | C33: HS-23 s.8.0 / Appendix 6 | D33: 4 | F33: =IF(E33="","",IF(UPPER(E33)="N/A","N/A",D33*E33)) | G33: • Self-neglect assessment • MDT engagement
... A44: SG-23 | B44: Service Users at higher risk (cognitive impairment, isolation, complex family dynamics) have a documented individual safeguarding risk assessment | C44: HS-23 s.7.6 | D44: 4 | F44: =IF(E44="","",IF(UPPER(E44)="N/A","N/A",D44*E44)) | G44: • Individual safeguarding risk in care plan • Review frequency
A46: COMPLIANCE SUMMARY
A47: Achieved weighted score | B47: =SUMPRODUCT(IFERROR((F22:F44+0),0)) -> 0 | C47: Max possible (excl N/A) | D47: =SUMPRODUCT((F22:F44<>"N/A")*(F22:F44<>"")*(D22:D44*2)) -> 0 | E47: Compliance % | F47: =IFERROR(B47/D47,"") | G47: Rating | H47: =IFERROR(IF(F47="","",IF(F47>=0.95,"Compliant",IF(F47>=0.85,"Substantially compliant",IF(F47>=0.7,"Partially compliant","Non-compliant")))),"")
A49: Rating thresholds: Compliant ≥95% · Substantially compliant 85-94.9% · Partially compliant 70-84.9% · Non-compliant <70%
A51: KEY FINDINGS
A52: [Auditor: summarise the main findings — strengths, areas of partial compliance and areas of non-compliance. Reference criterion IDs where relevant.]
A57: RECOMMENDATIONS
A58: [Auditor: list specific, actionable recommendations to address the findings. Each will become a QIP.]
A62: ACTION PLAN
A63: # | B63: Action | C63: Owner | D63: Target date | E63: Status | F63: Linked QIP ID | G63: Evidence of completion | H63: Closed date
A64: 1
...

Sheet CMP-01 Complaints Handling Audi
A1: AUD-CMP-01 · Complaints Handling Audit
A3: Audit code | B3: AUD-CMP-01
A4: Title | B4: Complaints Handling Audit
A5: Source policies | B5: QA-03, QA-03.2, QA-SOP-CMP-01
A6: Owner | B6: Complaints Review Officer (per QA-03 s.5.5) with independent oversight by Director of Quality
A7: Frequency | B7: Annual full audit, plus quarterly KPI review aligned to QA-03 s.15.0 Quarterly Report to the HSE
A8: Auditor name | B8: [enter auditor name]
A9: Audit period | B9: [enter audit period]
A10: Sample size | B10: [enter sample size]
A12: SCOPE & SAMPLING METHODOLOGY
A13: Scope | B13: All complaints (formal and point-of-contact) and all Service User feedback recorded in the audit period. Includes the Master Complaints Log, individual case files, and outbound communication to complainants.
A14: Sampling | B14: 100% review of formally logged complaints (volume typically permits full review). For point-of-contact resolutions: 30% random sample from the local-resolution log. For feedback: 20% random sample across the feedback channels listed in QA-03.2 s.7.1. Period: rolling 12 months. The audit is conducted by the Complaints Review Officer with the Director of Quality independently verifying timeliness, fairness and learning. Where the Complaints Officer was directly involved in a sampled case, an alternate reviewer is appointed to avoid conflict.
A15: Data sources | B15: • Master Complaints Log (QA-SOP-CMP-01) • Individual complaint files • Acknowledgement letters • Investigation reports and outcome letters • Complaints Review Officer decisions (Stage 2) • HSE Quarterly Reports submitted • Feedback Log (QA-03.2) • Service User Guide complaints section • Staff training records on complaints handling • CGC minutes covering complaints trends
A17: SCORING SCHEME
A18: 0 = Non-compliant · 1 = Partially compliant · 2 = Fully compliant · N/A = Not applicable. Weighted score = score × weight. Audit compliance % = sum of weighted scores ÷ (sum of maximum weighted scores, excluding N/A).
A20: AUDIT CRITERIA
A21: ID | B21: Criterion | C21: Policy ref | D21: Weight | E21: Score (0/1/2/N/A) | F21: Weighted score | G21: Evidence / observations | H21: Comments
A22: CMP-01 | B22: A Complaints Officer is named, current, and contactable; backup arrangements documented | C22: QA-03 s.5.4 | D22: 4 | F22: =IF(E22="","",IF(UPPER(E22)="N/A","N/A",D22*E22)) | G22: • Named officer in policy • Deputy arrangement
A23: CMP-02 | B23: Service Users are informed of the complaints route at sign-up via the Service User Guide and Charter | C23: QA-03 s.6.1; GOV-12 | D23: 3 | F23: =IF(E23="","",IF(UPPER(E23)="N/A","N/A",D23*E23)) | G23: • Guide content • Sign-up checklist
A24: CMP-03 | B24: All complaints are logged in the Master Complaints Log within 1 working day of receipt | C24: QA-03 s.17.0 | D24: 4 | F24: =IF(E24="","",IF(UPPER(E24)="N/A","N/A",D24*E24)) | G24: • Log entry date vs receipt date • Sample timing
A25: CMP-04 | B25: Every complaint is acknowledged in writing within 5 working days | C25: QA-03 s.7.0 | D25: 5 | F25: =IF(E25="","",IF(UPPER(E25)="N/A","N/A",D25*E25)) | G25: • Acknowledgement letter on file • Date check
A26: CMP-05 | B26: Investigation outcome letter issued within 30 working days, or extension communicated in writing with reasons | C26: QA-03 s.9.0 | D26: 5 | F26: =IF(E26="","",IF(UPPER(E26)="N/A","N/A",D26*E26)) | G26: • Outcome letter date • Extension notice if any
A27: CMP-06 | B27: Complainants are informed of their right to internal review and external HSE / Ombudsman onward routes | C27: QA-03 s.9.0 / s.10.0 | D27: 4 | F27: =IF(E27="","",IF(UPPER(E27)="N/A","N/A",D27*E27)) | G27: • Outcome letter content • Onward routes listed
A28: CMP-07 | B28: Point-of-contact resolutions are still recorded centrally | C28: QA-03 s.6.4 | D28: 3 | F28: =IF(E28="","",IF(UPPER(E28)="N/A","N/A",D28*E28)) | G28: • Local-resolution log • Sample for full content
A29: CMP-08 | B29: Vexatious / unreasonable behaviour cases are managed per QA-03 s.13.0 with proportionate response | C29: QA-03 s.13.0 | D29: 3 | F29: =IF(E29="","",IF(UPPER(E29)="N/A","N/A",D29*E29)) | G29: • Decision rationale • Escalation route
A30: CMP-09 | B30: Time limits for raising complaints (12 months) are applied consistently and extensions documented | C30: QA-03 s.6.1 / s.8.0 | D30: 3 | F30: =IF(E30="","",IF(UPPER(E30)="N/A","N/A",D30*E30)) | G30: • Extension log • Rationale
A31: CMP-10 | B31: Complaints relating to safeguarding are routed to the DSO in parallel with the complaints process | C31: QA-03 s.11.0 | D31: 5 | F31: =IF(E31="","",IF(UPPER(E31)="N/A","N/A",D31*E31)) | G31: • Cross-reference SG log • Dual-track record
A32: CMP-11 | B32: Complaints relating to incidents trigger an incident report (QA-13) | C32: QA-13 s.7.1 | D32: 5 | F32: =IF(E32="","",IF(UPPER(E32)="N/A","N/A",D32*E32)) | G32: • Cross-reference incident log • Linked case IDs
A33: CMP-12 | B33: Complaint files contain all required elements: complaint letter, acknowledgement, investigation plan, evidence, outcome, complainant response | C33: QA-03 s.17.0 | D33: 3 | F33: =IF(E33="","",IF(UPPER(E33)="N/A","N/A",D33*E33)) | G33: • File completeness checklist • Missing element list
... A43: CMP-22 | B43: Excluded matters (QA-03 s.11.0) are correctly identified and redirected to the appropriate process | C43: QA-03 s.11.0 | D43: 3 | F43: =IF(E43="","",IF(UPPER(E43)="N/A","N/A",D43*E43)) | G43: • Exclusion log • Redirection letters
A45: COMPLIANCE SUMMARY
A46: Achieved weighted score | B46: =SUMPRODUCT(IFERROR((F22:F43+0),0)) -> 0 | C46: Max possible (excl N/A) | D46: =SUMPRODUCT((F22:F43<>"N/A")*(F22:F43<>"")*(D22:D43*2)) -> 0 | E46: Compliance % | F46: =IFERROR(B46/D46,"") | G46: Rating | H46: =IFERROR(IF(F46="","",IF(F46>=0.95,"Compliant",IF(F46>=0.85,"Substantially compliant",IF(F46>=0.7,"Partially compliant","Non-compliant")))),"")
A48: Rating thresholds: Compliant ≥95% · Substantially compliant 85-94.9% · Partially compliant 70-84.9% · Non-compliant <70%
A50: KEY FINDINGS
A51: [Auditor: summarise the main findings — strengths, areas of partial compliance and areas of non-compliance. Reference criterion IDs where relevant.]
A56: RECOMMENDATIONS
A57: [Auditor: list specific, actionable recommendations to address the findings. Each will become a QIP.]
A61: ACTION PLAN
A62: # | B62: Action | C62: Owner | D62: Target date | E62: Status | F62: Linked QIP ID | G62: Evidence of completion | H62: Closed date
A63: 1
...

Sheet FIN-01 Financial Protection Aud
A1: AUD-FIN-01 · Financial Protection Audit
A3: Audit code | B3: AUD-FIN-01
A4: Title | B4: Financial Protection Audit
A5: Source policies | B5: CARE-09, CARE-17
A6: Owner | B6: Director of Care (per CARE-09 s.5.4 and CARE-17 s.5.0) with independent verification by Director of Quality. The Director of Care holds quarterly audit responsibility per CARE-17 s.8.10.
A7: Frequency | B7: Quarterly audit of Financial Transactions records (mandated by CARE-17 s.8.10); annual full audit covering all controls
A8: Auditor name | B8: [enter auditor name]
A9: Audit period | B9: [enter audit period]
A10: Sample size | B10: [enter sample size]
A12: SCOPE & SAMPLING METHODOLOGY
A13: Scope | B13: All Service User Financial Transactions records, all staff gifts / declarations of interest, any reported or suspected financial abuse cases, and the prevention controls (training, vetting, supervision). Does not extend to Service Users own bank accounts beyond what staff record on Liberty Living forms.
A14: Sampling | B14: 100% review of all Financial Transactions Templates submitted in the audit period (transactions are individually loggable per CARE-17 s.8.4). Plus 100% of any reported financial abuse alerts. For prevention controls: stratified 20% sample of Service User files where shopping or transaction support is part of the plan, plus 100% staff gifts/conflict declarations register. Period: rolling 12 months (quarterly audits cover the preceding quarter). The audit is performed by the Director of Care with independent verification of a random 10% by the Director of Quality.
A15: Data sources | B15: • Financial Transactions Template records (CARE-17 Appendix 1) • Receipts retained on file (CARE-17 s.8.5) • Service User Home Support Plans - financial / shopping tasks • Staff gifts and conflict-of-interest register • DSO log of financial abuse alerts • Incident log (QA-13) - financial category • CARE-09 / CARE-17 training records • HSE Safeguarding referrals related to financial concerns • Quarterly audit reports by Director of Care • Service User Charter and Service User Guide - financial sections
A17: SCORING SCHEME
A18: 0 = Non-compliant · 1 = Partially compliant · 2 = Fully compliant · N/A = Not applicable. Weighted score = score × weight. Audit compliance % = sum of weighted scores ÷ (sum of maximum weighted scores, excluding N/A).
A20: AUDIT CRITERIA
A21: ID | B21: Criterion | C21: Policy ref | D21: Weight | E21: Score (0/1/2/N/A) | F21: Weighted score | G21: Evidence / observations | H21: Comments
A22: FIN-01 | B22: Every transaction involving Service User money by staff is recorded on the Financial Transactions Template | C22: CARE-17 s.8.4 | D22: 5 | F22: =IF(E22="","",IF(UPPER(E22)="N/A","N/A",D22*E22)) | G22: • Sample of transactions cross-referenced with visit logs • Look for unrecorded shopping trips
A23: FIN-02 | B23: Each transaction record includes date, amount given, items purchased, amount returned, receipts attached | C23: CARE-17 s.8.4 / s.8.5 | D23: 5 | F23: =IF(E23="","",IF(UPPER(E23)="N/A","N/A",D23*E23)) | G23: • Field-by-field completeness check • Receipt attached or rationale for missing
A24: FIN-03 | B24: Each transaction is countersigned by the Service User or representative | C24: CARE-17 s.8.4 | D24: 5 | F24: =IF(E24="","",IF(UPPER(E24)="N/A","N/A",D24*E24)) | G24: • Signature present • Rationale if signature not possible (e.g. cognitive impairment - alternative attestation)
A25: FIN-04 | B25: Staff do not receive gifts, money or property from Service Users beyond the de minimis allowed in policy | C25: CARE-09 s.6.3; CARE-17 s.7.1 | D25: 5 | F25: =IF(E25="","",IF(UPPER(E25)="N/A","N/A",D25*E25)) | G25: • Gifts declaration register • Staff confirmations
A26: FIN-05 | B26: Staff do not hold ATM cards, PINs, or banking passwords for Service Users | C26: CARE-17 s.7.2 | D26: 5 | F26: =IF(E26="","",IF(UPPER(E26)="N/A","N/A",D26*E26)) | G26: • Staff knowledge check • Visit observations
A27: FIN-06 | B27: Staff do not mix personal and Service User funds, and do not borrow from / lend to Service Users | C27: CARE-09 s.6.5 | D27: 5 | F27: =IF(E27="","",IF(UPPER(E27)="N/A","N/A",D27*E27)) | G27: • Staff declarations • Transaction record review
A28: FIN-07 | B28: Personal loyalty cards (e.g. Tesco Clubcard) are not used when shopping for Service Users | C28: CARE-17 s.8.6 | D28: 3 | F28: =IF(E28="","",IF(UPPER(E28)="N/A","N/A",D28*E28)) | G28: • Staff knowledge check • Receipt inspection for loyalty card use
A29: FIN-08 | B29: Large or inappropriate amounts of cash held by Service Users are reported per CARE-17 s.8.7 | C29: CARE-17 s.8.7 | D29: 4 | F29: =IF(E29="","",IF(UPPER(E29)="N/A","N/A",D29*E29)) | G29: • Alert log • Plan note
A30: FIN-09 | B30: Staff are vigilant for indicators of financial abuse listed in CARE-09 s.7.1 and act on them | C30: CARE-09 s.7.1 / s.7.2 | D30: 5 | F30: =IF(E30="","",IF(UPPER(E30)="N/A","N/A",D30*E30)) | G30: • Concerns log • Escalation records
A31: FIN-10 | B31: Financial abuse concerns are escalated to the DSO and, where appropriate, HSE Safeguarding Team | C31: CARE-09 s.7.4; CARE-17 s.8.9 | D31: 5 | F31: =IF(E31="","",IF(UPPER(E31)="N/A","N/A",D31*E31)) | G31: • DSO file cross-check • HSE referral evidence
A32: FIN-11 | B32: Quarterly financial transactions audit by Director of Care has been completed for each quarter in the period | C32: CARE-17 s.8.10 | D32: 4 | F32: =IF(E32="","",IF(UPPER(E32)="N/A","N/A",D32*E32)) | G32: • Quarterly audit report on file • EMT/CGC tabling
A33: FIN-12 | B33: All staff completed Financial Abuse / Money Handling training in the last 12 months | C33: CARE-09 s.8.0 | D33: 4 | F33: =IF(E33="","",IF(UPPER(E33)="N/A","N/A",D33*E33)) | G33: • Training matrix • Refresher dates
... A41: FIN-20 | B41: Conflicts of interest (e.g. staff related to Service Users) are declared and managed | C41: HR-38; CARE-09 | D41: 4 | F41: =IF(E41="","",IF(UPPER(E41)="N/A","N/A",D41*E41)) | G41: • Conflict register • Allocation adjustment evidence
A43: COMPLIANCE SUMMARY
A44: Achieved weighted score | B44: =SUMPRODUCT(IFERROR((F22:F41+0),0)) -> 0 | C44: Max possible (excl N/A) | D44: =SUMPRODUCT((F22:F41<>"N/A")*(F22:F41<>"")*(D22:D41*2)) -> 0 | E44: Compliance % | F44: =IFERROR(B44/D44,"") | G44: Rating | H44: =IFERROR(IF(F44="","",IF(F44>=0.95,"Compliant",IF(F44>=0.85,"Substantially compliant",IF(F44>=0.7,"Partially compliant","Non-compliant")))),"")
A46: Rating thresholds: Compliant ≥95% · Substantially compliant 85-94.9% · Partially compliant 70-84.9% · Non-compliant <70%
A48: KEY FINDINGS
A49: [Auditor: summarise the main findings — strengths, areas of partial compliance and areas of non-compliance. Reference criterion IDs where relevant.]
A54: RECOMMENDATIONS
A55: [Auditor: list specific, actionable recommendations to address the findings. Each will become a QIP.]
A59: ACTION PLAN
A60: # | B60: Action | C60: Owner | D60: Target date | E60: Status | F60: Linked QIP ID | G60: Evidence of completion | H60: Closed date
A61: 1
...

Sheet LW-01 Lone Worker Audit
A1: AUD-LW-01 · Lone Worker Audit
A3: Audit code | B3: AUD-LW-01
A4: Title | B4: Lone Worker Audit
A5: Source policies | B5: HS-16, HS-10
A6: Owner | B6: Director of Operations (per HS-16 s.5.4) with independent verification by Director of Quality
A7: Frequency | B7: Annual full audit, plus quarterly review of lone-working incidents, missed control-point contacts, and aggression incidents
A8: Auditor name | B8: [enter auditor name]
A9: Audit period | B9: [enter audit period]
A10: Sample size | B10: [enter sample size]
A12: SCOPE & SAMPLING METHODOLOGY
A13: Scope | B13: All HCAs and any other staff who work alone or visit Service Users homes; all Lone Worker Risk Assessments (general and Service-User-specific); the Control Point system; the response process to failed contacts; and the use of NFC tags or equivalent monitoring technology.
A14: Sampling | B14: Two parallel samples. (1) Service User sample: stratified random 20% sample of Service User packages plus 100% of packages flagged as elevated lone-working risk. (2) Staff sample: 25% of HCAs, with 100% of those who reported a lone-working incident in the period. Period: rolling 12 months. The Control Point function and call-handling response are tested via 5 unannounced scenarios (simulated failed contacts) over the audit period.
A15: Data sources | B15: • Lone Worker General Risk Assessment (HS-16 Appendix 2) • Service User Lone Worker Risk Assessments • Home Environmental Risk Assessments (HS-24) • NFC tag / electronic monitoring logs • Control Point shift logs • Incident reports - aggression, assault, near-miss, missed contact • Training records (Lone Worker, Personal Safety, Conflict Resolution) • Vehicle / travel records where relevant • Staff supervision notes referencing lone working concerns • Mobile phone / panic alarm deployment records
A17: SCORING SCHEME
A18: 0 = Non-compliant · 1 = Partially compliant · 2 = Fully compliant · N/A = Not applicable. Weighted score = score × weight. Audit compliance % = sum of weighted scores ÷ (sum of maximum weighted scores, excluding N/A).
A20: AUDIT CRITERIA
A21: ID | B21: Criterion | C21: Policy ref | D21: Weight | E21: Score (0/1/2/N/A) | F21: Weighted score | G21: Evidence / observations | H21: Comments
A22: LW-01 | B22: A Lone Worker General Risk Assessment is in place, current (reviewed in last 12 months), and signed off | C22: HS-16 s.6.1 / s.6.2 | D22: 5 | F22: =IF(E22="","",IF(UPPER(E22)="N/A","N/A",D22*E22)) | G22: • Locate assessment • Review date check
A23: LW-02 | B23: Every Service User package has a documented lone-working risk consideration as part of the assessment | C23: HS-16 s.7.1 / s.7.2 | D23: 5 | F23: =IF(E23="","",IF(UPPER(E23)="N/A","N/A",D23*E23)) | G23: • Sample plans for LW section • Risk rating present
A24: LW-03 | B24: Where elevated risks were identified, a full Service-User-specific Lone Worker Risk Assessment was completed | C24: HS-16 s.7.3 | D24: 5 | F24: =IF(E24="","",IF(UPPER(E24)="N/A","N/A",D24*E24)) | G24: • Full LW assessment on file • Control measures listed
A25: LW-04 | B25: Where risk to staff is deemed unacceptable, action is taken (e.g. paired visit, withdrawal of service) and documented | C25: HS-16 s.7.5 | D25: 5 | F25: =IF(E25="","",IF(UPPER(E25)="N/A","N/A",D25*E25)) | G25: • Mitigation decisions on file • Service adjustment evidence
A26: LW-05 | B26: Control Point function is operational 24/7 with documented call handling and escalation tree | C26: HS-16 s.10.0 | D26: 5 | F26: =IF(E26="","",IF(UPPER(E26)="N/A","N/A",D26*E26)) | G26: • Control Point SOP • Shift logs
A27: LW-06 | B27: Failed-contact follow-up procedure (HS-16 s.11.0) is in place and tested | C27: HS-16 s.11.0 | D27: 5 | F27: =IF(E27="","",IF(UPPER(E27)="N/A","N/A",D27*E27)) | G27: • Test scenarios • Response time data
A28: LW-07 | B28: NFC tag or equivalent visit-confirmation technology is deployed for all in-home visits | C28: HS-16 Appendix 3 | D28: 4 | F28: =IF(E28="","",IF(UPPER(E28)="N/A","N/A",D28*E28)) | G28: • Tag log audit • Missed-tap analysis
A29: LW-08 | B29: Missed taps or unconfirmed visits are followed up by Control Point and the outcome recorded | C29: HS-16 s.11.0 | D29: 4 | F29: =IF(E29="","",IF(UPPER(E29)="N/A","N/A",D29*E29)) | G29: • Follow-up records • Closure evidence
A30: LW-09 | B30: Staff carry a charged mobile phone with key contacts and panic-alarm function accessible | C30: HS-16 s.8.0; HS-24 s.10.0 | D30: 4 | F30: =IF(E30="","",IF(UPPER(E30)="N/A","N/A",D30*E30)) | G30: • Issued device list • Charging policy
A31: LW-10 | B31: Personal safety controls per HS-16 Appendix 4, 5 and 6 are communicated and reinforced | C31: HS-16 s.8.1 / Appendices 4/5/6 | D31: 3 | F31: =IF(E31="","",IF(UPPER(E31)="N/A","N/A",D31*E31)) | G31: • Briefing record • Refresher attendance
A32: LW-11 | B32: Incidents of aggression or assault are reported per HS-16 s.12.0 and QA-13, and victims supported | C32: HS-16 s.12.0; QA-13 | D32: 5 | F32: =IF(E32="","",IF(UPPER(E32)="N/A","N/A",D32*E32)) | G32: • Incident reports • Staff support records
A33: LW-12 | B33: Staff received Lone Worker training as part of induction and at refresher intervals | C33: HS-16 s.13.0; HR-14 | D33: 4 | F33: =IF(E33="","",IF(UPPER(E33)="N/A","N/A",D33*E33)) | G33: • Training matrix • Refresher dates
... A41: LW-20 | B41: Lone-working KPIs (e.g. missed-tap rate, aggression incident rate) are reported monthly to EMT | C41: HS-16 s.13.0; HS-10 s.7.1 | D41: 3 | F41: =IF(E41="","",IF(UPPER(E41)="N/A","N/A",D41*E41)) | G41: • KPI dashboard • EMT pack
A43: COMPLIANCE SUMMARY
A44: Achieved weighted score | B44: =SUMPRODUCT(IFERROR((F22:F41+0),0)) -> 0 | C44: Max possible (excl N/A) | D44: =SUMPRODUCT((F22:F41<>"N/A")*(F22:F41<>"")*(D22:D41*2)) -> 0 | E44: Compliance % | F44: =IFERROR(B44/D44,"") | G44: Rating | H44: =IFERROR(IF(F44="","",IF(F44>=0.95,"Compliant",IF(F44>=0.85,"Substantially compliant",IF(F44>=0.7,"Partially compliant","Non-compliant")))),"")
A46: Rating thresholds: Compliant ≥95% · Substantially compliant 85-94.9% · Partially compliant 70-84.9% · Non-compliant <70%
A48: KEY FINDINGS
A49: [Auditor: summarise the main findings — strengths, areas of partial compliance and areas of non-compliance. Reference criterion IDs where relevant.]
A54: RECOMMENDATIONS
A55: [Auditor: list specific, actionable recommendations to address the findings. Each will become a QIP.]
A59: ACTION PLAN
A60: # | B60: Action | C60: Owner | D60: Target date | E60: Status | F60: Linked QIP ID | G60: Evidence of completion | H60: Closed date
A61: 1
...

Sheet ENV-01 Environmental Safety Aud
A1: AUD-ENV-01 · Environmental Safety Audit
A3: Audit code | B3: AUD-ENV-01
A4: Title | B4: Environmental Safety Audit
A5: Source policies | B5: HS-24, HS-10, HS-31
A6: Owner | B6: Director of Operations (per HS-24 s.4.5) with verification by Director of Quality
A7: Frequency | B7: Annual full audit, plus quarterly review of new Home Environmental Risk Assessments and any environment-related incidents
A8: Auditor name | B8: [enter auditor name]
A9: Audit period | B9: [enter audit period]
A10: Sample size | B10: [enter sample size]
A12: SCOPE & SAMPLING METHODOLOGY
A13: Scope | B13: All Service Users Home Environmental Risk Assessments, security and access arrangements, staff ID and uniform compliance, mobile phone usage in homes, and the corporate health and safety risk register as it relates to home-environment risks.
A14: Sampling | B14: Stratified random sample of 20% of active Service User packages or 50 plans (whichever is greater), with 100% inclusion of packages where an environmental incident occurred in the period. Period: rolling 12 months. Observation component: accompany 10 HCAs on visits (with Service User consent) to confirm entry procedures, ID display, and environmental controls in practice.
A15: Data sources | B15: • Home Environmental Risk Assessments (CARE-08 Appendix 8; HS-24) • Home Support Care Plans - environmental controls section • Key safe / access arrangements register (HS-24 s.7.0) • Staff ID card register • Uniform / dress code policy and compliance observations • Mobile phone usage records / staff acknowledgements • Incident log - environmental category (slips/trips, fire, electrical, pets, hazardous substances) • Corporate health and safety risk register (HS-10) • BeSMART safety statement records • Re-assessment triggers logged when Service User home changes
A17: SCORING SCHEME
A18: 0 = Non-compliant · 1 = Partially compliant · 2 = Fully compliant · N/A = Not applicable. Weighted score = score × weight. Audit compliance % = sum of weighted scores ÷ (sum of maximum weighted scores, excluding N/A).
A20: AUDIT CRITERIA
A21: ID | B21: Criterion | C21: Policy ref | D21: Weight | E21: Score (0/1/2/N/A) | F21: Weighted score | G21: Evidence / observations | H21: Comments
A22: ENV-01 | B22: A Home Environmental Risk Assessment exists for every sampled Service User, completed before service commencement | C22: HS-24 s.6.2 | D22: 5 | F22: =IF(E22="","",IF(UPPER(E22)="N/A","N/A",D22*E22)) | G22: • Locate ERA • Date predates first visit
A23: ENV-02 | B23: ERA covers all HS-24 s.6.3 domains (access, fire, electrical, fall hazards, pets, hazardous substances, smoking) | C23: HS-24 s.6.3 | D23: 4 | F23: =IF(E23="","",IF(UPPER(E23)="N/A","N/A",D23*E23)) | G23: • Domain checklist • Blank fields rationale
A24: ENV-03 | B24: Risk levels are scored and control measures defined for each identified hazard | C24: HS-24 s.6.4 | D24: 4 | F24: =IF(E24="","",IF(UPPER(E24)="N/A","N/A",D24*E24)) | G24: • Risk matrix application • Controls listed
A25: ENV-04 | B25: Where controls are insufficient or refused, the matter is escalated and the decision to provide/withdraw service is documented | C25: HS-24 s.6.4; HS-10 s.6.7 | D25: 5 | F25: =IF(E25="","",IF(UPPER(E25)="N/A","N/A",D25*E25)) | G25: • Escalation log • Decision rationale
A26: ENV-05 | B26: ERAs are re-assessed when Service User home environment changes or following an incident | C26: HS-24 s.6.6 | D26: 4 | F26: =IF(E26="","",IF(UPPER(E26)="N/A","N/A",D26*E26)) | G26: • Re-assessment trigger evidence • Updated ERA on file
A27: ENV-06 | B27: Access and key-safe arrangements are documented securely with appropriate access controls | C27: HS-24 s.7.1 / s.7.2 | D27: 5 | F27: =IF(E27="","",IF(UPPER(E27)="N/A","N/A",D27*E27)) | G27: • Access register security • Authorised staff list
A28: ENV-07 | B28: Staff only access Service User homes during scheduled duties | C28: HS-24 s.7.3 | D28: 4 | F28: =IF(E28="","",IF(UPPER(E28)="N/A","N/A",D28*E28)) | G28: • NFC log analysis • Roster cross-check
A29: ENV-08 | B29: Staff announce arrival and confirm identity using Liberty Living ID on entry | C29: HS-24 s.7.6 / s.8.0 | D29: 4 | F29: =IF(E29="","",IF(UPPER(E29)="N/A","N/A",D29*E29)) | G29: • Observation evidence • Service User feedback
A30: ENV-09 | B30: Failed-entry procedure (HS-24 s.7.7 / s.7.8) is followed when Service User does not answer | C30: HS-24 s.7.7 / s.7.8 | D30: 5 | F30: =IF(E30="","",IF(UPPER(E30)="N/A","N/A",D30*E30)) | G30: • Incident logs of failed entries • Welfare check evidence
A31: ENV-10 | B31: All staff hold current Liberty Living ID cards and display them on visits | C31: HS-24 s.8.0 | D31: 3 | F31: =IF(E31="","",IF(UPPER(E31)="N/A","N/A",D31*E31)) | G31: • ID register • Observation
A32: ENV-11 | B32: Uniform / dress code policy is communicated and adhered to | C32: HS-24 s.9.0 | D32: 2 | F32: =IF(E32="","",IF(UPPER(E32)="N/A","N/A",D32*E32)) | G32: • Observation • Staff awareness
A33: ENV-12 | B33: Mobile phone usage in Service Users homes complies with HS-24 s.10.0 | C33: HS-24 s.10.0 | D33: 2 | F33: =IF(E33="","",IF(UPPER(E33)="N/A","N/A",D33*E33)) | G33: • Staff briefing record • Complaint review
... A43: ENV-22 | B43: Service User feedback / complaints relating to environmental matters are reviewed and actioned | C43: HS-24 s.13.0; QA-03.2 | D43: 2 | F43: =IF(E43="","",IF(UPPER(E43)="N/A","N/A",D43*E43)) | G43: • Complaints log subset • Closure action
A45: COMPLIANCE SUMMARY
A46: Achieved weighted score | B46: =SUMPRODUCT(IFERROR((F22:F43+0),0)) -> 0 | C46: Max possible (excl N/A) | D46: =SUMPRODUCT((F22:F43<>"N/A")*(F22:F43<>"")*(D22:D43*2)) -> 0 | E46: Compliance % | F46: =IFERROR(B46/D46,"") | G46: Rating | H46: =IFERROR(IF(F46="","",IF(F46>=0.95,"Compliant",IF(F46>=0.85,"Substantially compliant",IF(F46>=0.7,"Partially compliant","Non-compliant")))),"")
A48: Rating thresholds: Compliant ≥95% · Substantially compliant 85-94.9% · Partially compliant 70-84.9% · Non-compliant <70%
A50: KEY FINDINGS
A51: [Auditor: summarise the main findings — strengths, areas of partial compliance and areas of non-compliance. Reference criterion IDs where relevant.]
A56: RECOMMENDATIONS
